Workbook

Sheet Инструкция
B2: Модель TCO (Total Cost of Ownership) — кейс «Africa Delivery», горизонт 5 лет
B4: Зачем этот файл
B5: Задача | C5: Оценить полную стоимость владения выбранным архитектурным вариантом на 5 лет и использовать цифры как аргумент в ADR №1 («Выбор архитектурного стиля»).
B6: Как использовать | C6: Заполни один и тот же шаблон для каждого рассматриваемого варианта (например: модульный монолит / SOA / микросервисы) — сравнивать нужно итоги, а не ощущения.
B8: Цветовая легенда
B9: Синий текст на жёлтом фоне | C9: Ячейки для заполнения. Только их и редактируем.
B10: Чёрный текст | C10: Формулы. Не трогаем — пересчитаются сами.
B11: Зелёный текст | C11: Ссылка на лист «Допущения».
B13: Порядок работы
B14: Шаг 1 | C14: Лист «Допущения» → блок 1: вбить драйверы бизнеса по годам (активные пользователи, число заказов, средний чек). Из них считается GMV.
B15: Шаг 2 | C15: Лист «Допущения» → блок 2: финансовые допущения (инфляция, рост ФОТ, ставка дисконтирования, резерв, целевой SLO).
B16: Шаг 3 | C16: Лист «TCO» → в колонке «База, $/год (Год 1)» указать затраты первого года по каждой статье. Лишние статьи оставить пустыми, свои — дописать в свободные строки.
B17: Шаг 4 | C17: Лист «TCO» → в колонке «Драйвер роста» выбрать из выпадающего списка, от чего растёт статья: фикс / инфляция / ФОТ / пользователи / заказы / GMV. Годы 2–5 посчитаются сами.
B18: Шаг 5 | C18: Посмотреть блок «Ключевые метрики» внизу листа «TCO»: итог за 5 лет, NPV, стоимость на заказ, проверку бюджета CFO ($9k/мес на облако).
B20: Что важно не забыть в этом кейсе
B21: Бюджет CFO | C21: $9 000/мес на облако на старте. Если Год 1 в блоке «Облачная инфраструктура» не проходит — это архитектурное решение, а не ошибка модели: опиши, что урезаешь.
B22: Цена простоя | C22: Инвестор оценивает минуту простоя в $12 000. Целевой SLO 99,99% = 52,6 мин/год ≈ $631k. Этот риск считается отдельным блоком — сравни его со стоимостью резервирования.
B23: Транзакционные расходы | C23: Комиссии M-Pesa / Flutterwave / Paystack, SMS и WhatsApp растут с GMV и числом заказов и на горизонте 5 лет обычно обгоняют инфраструктуру. Не забудь их — это типичная ошибка.
B24: Сравнение вариантов | C24: Транзакционные расходы (блок 3) почти одинаковы для любой архитектуры — это pass-through от оборота. Варианты архитектуры сравнивай по блокам 1, 2, 4 и 6.
B25: Разовые затраты | C25: Комплаенс-аудит NDPR/POPIA, пентест, миграция — если статья возникает не каждый год, просто перезапиши формулу в нужной ячейке года числом (и покрась в синий).
B26: Люди | C26: ФОТ команды — обычно самая крупная статья TCO. Микросервисы дешевле в масштабировании, но дороже в эксплуатации: это должно быть видно в цифрах, а не только в тексте ADR.
B28: Все числа в файле — примеры для демонстрации формата. Замени их своими оценками и укажи источник в колонке «Комментарий / источник».

Sheet Допущения
B2: Допущения модели TCO — Africa Delivery
B3: Заполняются только ячейки с жёлтой заливкой. Все числа ниже — пример, заменить своими.
B5: 1. Драйверы бизнеса — заполнить
B6: Показатель | C6: Год 1 | D6: Год 2 | E6: Год 3 | F6: Год 4 | G6: Год 5 | H6: Комментарий / источник
B7: Активные пользователи (на конец года) | C7: 50000 | D7: 300000 | E7: 1000000 | F7: 2500000 | G7: 5000000 | H7: Цель кейса: 1М+ пользователей к 12 месяцам, 5 стран
B8: Число заказов в год | C8: 600000 | D8: 3600000 | E8: 12000000 | F8: 30000000 | G8: 60000000 | H8: MVP: 100 продавцов, 5000 SKU. Оценка студента
B9: Средний чек (AOV), $ | C9: 25 | D9: 26 | E9: 27 | F9: 28 | G9: 29 | H9: Оценка студента по рынку (Jumia / Takealot)
B10: GMV, $ в год (расчёт) | C10: =C8*C9 -> 15000000 | D10: =D8*D9 -> 93600000 | E10: =E8*E9 -> 324000000 | F10: =F8*F9 -> 840000000 | G10: =G8*G9 -> 1740000000 | H10: Расчёт: заказы × средний чек
B12: 2. Финансовые допущения — заполнить
B13: Параметр | C13: Значение | H13: Комментарий / источник
B14: Инфляция затрат, % в год | C14: 0.12 | H14: Применяется к статьям с драйвером «инфляция»
B15: Рост ФОТ, % в год | C15: 0.08 | H15: Рынок переполнен айти-специалистами => ниже инфляции (примерно на уровне индексации)
B16: Ставка дисконтирования, % в год | C16: 0.25 | H16: Для расчёта NPV затрат. Стартап, высокий риск
B17: Резерв на непредвиденное (contingency), % | C17: 0.2 | H17: Надбавка к прямым затратам
B18: Бюджет CFO на облако, $/мес | C18: 9000 | H18: Ограничение из письма CFO
B19: Стоимость минуты простоя, $ | C19: 12000 | H19: Оценка инвестора из условия кейса
B20: Целевой SLO (доступность), % | C20: 0.9999 | H20: Mission critical: 99,99% = 52,6 мин/год
B21: Учитывать стоимость простоя в TCO (1 — да, 0 — нет) | C21: 1 | H21: Переключатель для сценарного анализа
B23: 3. Индексы роста — расчёт, не редактировать
B24: Драйвер | C24: Год 1 | D24: Год 2 | E24: Год 3 | F24: Год 4 | G24: Год 5 | H24: Как считается
B25: фикс | C25: 1 | D25: 1 | E25: 1 | F25: 1 | G25: 1 | H25: Затраты не меняются по годам
B26: инфляция | C26: 1 | D26: =C26*(1+$C$14) -> 1.12 | E26: =D26*(1+$C$14) -> 1.2544 | F26: =E26*(1+$C$14) -> 1.404928 | G26: =F26*(1+$C$14) -> 1.5735194 | H26: Год N = Год N-1 × (1 + инфляция)
B27: ФОТ | C27: 1 | D27: =C27*(1+$C$15) -> 1.08 | E27: =D27*(1+$C$15) -> 1.1664 | F27: =E27*(1+$C$15) -> 1.259712 | G27: =F27*(1+$C$15) -> 1.360489 | H27: Год N = Год N-1 × (1 + рост ФОТ)
B28: пользователи | C28: =C7/$C$7 -> 1 | D28: =D7/$C$7 -> 6 | E28: =E7/$C$7 -> 20 | F28: =F7/$C$7 -> 50 | G28: =G7/$C$7 -> 100 | H28: Пропорционально числу активных пользователей
B29: заказы | C29: =C8/$C$8 -> 1 | D29: =D8/$C$8 -> 6 | E29: =E8/$C$8 -> 20 | F29: =F8/$C$8 -> 50 | G29: =G8/$C$8 -> 100 | H29: Пропорционально числу заказов
B30: GMV | C30: =C10/$C$10 -> 1 | D30: =D10/$C$10 -> 6.24 | E30: =E10/$C$10 -> 21.6 | F30: =F10/$C$10 -> 56 | G30: =G10/$C$10 -> 116 | H30: Пропорционально обороту
B32: Драйвер «пользователи» — упрощение: облачные расходы редко растут строго линейно (есть эффект масштаба и обратный эффект — рост нагрузки на БД). При желании введи свой драйвер отдельной строкой в таблице индексов.

Sheet TCO ММ
B2: TCO на 5 лет — Africa Delivery
B3: Заполняем колонки «Драйвер роста» и «База, $/год (Год 1)». Годы 1–5 считаются автоматически.
B5: Статья затрат | C5: Драйвер роста | D5: База, $/год (Год 1) | E5: Год 1 | F5: Год 2 | G5: Год 3 | H5: Год 4 | I5: Год 5 | J5: Итого 5 лет | K5: Доля | L5: Комментарий / источник
B6: БЛОК 1. Облачная инфраструктура (OpEx)
B7: Compute: ноды / контейнеры / serverless | C7: пользователи | D7: 8400 | E7: {=IF($D7="","",$D7*INDEX(Допущения!$C$25:$G$30,MATCH($C7,Допущения!$B$25:$B$30,0),1))} -> 8400 | F7: {=IF($D7="","",$D7*INDEX(Допущения!$C$25:$G$30,MATCH($C7,Допущения!$B$25:$B$30,0),2))} -> 50400 | G7: {=IF($D7="","",$D7*INDEX(Допущения!$C$25:$G$30,MATCH($C7,Допущения!$B$25:$B$30,0),3))} -> 168000 | H7: {=IF($D7="","",$D7*INDEX(Допущения!$C$25:$G$30,MATCH($C7,Допущения!$B$25:$B$30,0),4))} -> 420000 | I7: {=IF($D7="","",$D7*INDEX(Допущения!$C$25:$G$30,MATCH($C7,Допущения!$B$25:$B$30,0),5))} -> 840000 | J7: =SUM(E7:I7) -> 1486800 | L7: AWS af-south-1, оценка по калькулятору
B8: Управляемые БД (PostgreSQL, реплики) | C8: пользователи | D8: 3600 | E8: {=IF($D8="","",$D8*INDEX(Допущения!$C$25:$G$30,MATCH($C8,Допущения!$B$25:$B$30,0),1))} -> 3600 | F8: {=IF($D8="","",$D8*INDEX(Допущения!$C$25:$G$30,MATCH($C8,Допущения!$B$25:$B$30,0),2))} -> 21600 | G8: {=IF($D8="","",$D8*INDEX(Допущения!$C$25:$G$30,MATCH($C8,Допущения!$B$25:$B$30,0),3))} -> 72000 | H8: {=IF($D8="","",$D8*INDEX(Допущения!$C$25:$G$30,MATCH($C8,Допущения!$B$25:$B$30,0),4))} -> 180000 | I8: {=IF($D8="","",$D8*INDEX(Допущения!$C$25:$G$30,MATCH($C8,Допущения!$B$25:$B$30,0),5))} -> 360000 | J8: =SUM(E8:I8) -> 637200 | L8: Managed RDS + read replica
B9: Хранилище объектов и резервные копии | C9: пользователи | D9: 1800 | E9: {=IF($D9="","",$D9*INDEX(Допущения!$C$25:$G$30,MATCH($C9,Допущения!$B$25:$B$30,0),1))} -> 1800 | F9: {=IF($D9="","",$D9*INDEX(Допущения!$C$25:$G$30,MATCH($C9,Допущения!$B$25:$B$30,0),2))} -> 10800 | G9: {=IF($D9="","",$D9*INDEX(Допущения!$C$25:$G$30,MATCH($C9,Допущения!$B$25:$B$30,0),3))} -> 36000 | H9: {=IF($D9="","",$D9*INDEX(Допущения!$C$25:$G$30,MATCH($C9,Допущения!$B$25:$B$30,0),4))} -> 90000 | I9: {=IF($D9="","",$D9*INDEX(Допущения!$C$25:$G$30,MATCH($C9,Допущения!$B$25:$B$30,0),5))} -> 180000 | J9: =SUM(E9:I9) -> 318600 | L9: Фото товаров, 5000 SKU на старте
B10: CDN и исходящий трафик | C10: пользователи | D10: 3600 | E10: {=IF($D10="","",$D10*INDEX(Допущения!$C$25:$G$30,MATCH($C10,Допущения!$B$25:$B$30,0),1))} -> 3600 | F10: {=IF($D10="","",$D10*INDEX(Допущения!$C$25:$G$30,MATCH($C10,Допущения!$B$25:$B$30,0),2))} -> 21600 | G10: {=IF($D10="","",$D10*INDEX(Допущения!$C$25:$G$30,MATCH($C10,Допущения!$B$25:$B$30,0),3))} -> 72000 | H10: {=IF($D10="","",$D10*INDEX(Допущения!$C$25:$G$30,MATCH($C10,Допущения!$B$25:$B$30,0),4))} -> 180000 | I10: {=IF($D10="","",$D10*INDEX(Допущения!$C$25:$G$30,MATCH($C10,Допущения!$B$25:$B$30,0),5))} -> 360000 | J10: =SUM(E10:I10) -> 637200 | L10: 70% трафика — мобильный 3G, картинки WebP
B11: Очереди / стриминг (Kafka, SQS) | C11: пользователи | D11: 1200 | E11: {=IF($D11="","",$D11*INDEX(Допущения!$C$25:$G$30,MATCH($C11,Допущения!$B$25:$B$30,0),1))} -> 1200 | F11: {=IF($D11="","",$D11*INDEX(Допущения!$C$25:$G$30,MATCH($C11,Допущения!$B$25:$B$30,0),2))} -> 7200 | G11: {=IF($D11="","",$D11*INDEX(Допущения!$C$25:$G$30,MATCH($C11,Допущения!$B$25:$B$30,0),3))} -> 24000 | H11: {=IF($D11="","",$D11*INDEX(Допущения!$C$25:$G$30,MATCH($C11,Допущения!$B$25:$B$30,0),4))} -> 60000 | I11: {=IF($D11="","",$D11*INDEX(Допущения!$C$25:$G$30,MATCH($C11,Допущения!$B$25:$B$30,0),5))} -> 120000 | J11: =SUM(E11:I11) -> 212400 | L11: Асинхронные заказы и уведомления
B12: Резервный регион / DR | C12: пользователи | D12: 2400 | E12: {=IF($D12="","",$D12*INDEX(Допущения!$C$25:$G$30,MATCH($C12,Допущения!$B$25:$B$30,0),1))} -> 2400 | F12: {=IF($D12="","",$D12*INDEX(Допущения!$C$25:$G$30,MATCH($C12,Допущения!$B$25:$B$30,0),2))} -> 14400 | G12: {=IF($D12="","",$D12*INDEX(Допущения!$C$25:$G$30,MATCH($C12,Допущения!$B$25:$B$30,0),3))} -> 48000 | H12: {=IF($D12="","",$D12*INDEX(Допущения!$C$25:$G$30,MATCH($C12,Допущения!$B$25:$B$30,0),4))} -> 120000 | I12: {=IF($D12="","",$D12*INDEX(Допущения!$C$25:$G$30,MATCH($C12,Допущения!$B$25:$B$30,0),5))} -> 240000 | J12: =SUM(E12:I12) -> 424800 | L12: Зависит от выбранной стратегии RTO/RPO
B13: Локальное размещение данных (NDPR, Нигерия) | C13: инфляция | D13: 3000 | E13: {=IF($D13="","",$D13*INDEX(Допущения!$C$25:$G$30,MATCH($C13,Допущения!$B$25:$B$30,0),1))} -> 3000 | F13: {=IF($D13="","",$D13*INDEX(Допущения!$C$25:$G$30,MATCH($C13,Допущения!$B$25:$B$30,0),2))} -> 3360 | G13: {=IF($D13="","",$D13*INDEX(Допущения!$C$25:$G$30,MATCH($C13,Допущения!$B$25:$B$30,0),3))} -> 3763.2 | H13: {=IF($D13="","",$D13*INDEX(Допущения!$C$25:$G$30,MATCH($C13,Допущения!$B$25:$B$30,0),4))} -> 4214.784 | I13: {=IF($D13="","",$D13*INDEX(Допущения!$C$25:$G$30,MATCH($C13,Допущения!$B$25:$B$30,0),5))} -> 4720.5581 | J13: =SUM(E13:I13) -> 19058.542 | L13: Локальный провайдер или партнёр — см. ADR №3
B14: GPU-ноды | C14: пользователи | D14: 2400 | E14: {=IF($D14="","",$D14*INDEX(Допущения!$C$25:$G$30,MATCH($C14,Допущения!$B$25:$B$30,0),1))} -> 2400 | F14: {=IF($D14="","",$D14*INDEX(Допущения!$C$25:$G$30,MATCH($C14,Допущения!$B$25:$B$30,0),2))} -> 14400 | G14: {=IF($D14="","",$D14*INDEX(Допущения!$C$25:$G$30,MATCH($C14,Допущения!$B$25:$B$30,0),3))} -> 48000 | H14: {=IF($D14="","",$D14*INDEX(Допущения!$C$25:$G$30,MATCH($C14,Допущения!$B$25:$B$30,0),4))} -> 120000 | I14: {=IF($D14="","",$D14*INDEX(Допущения!$C$25:$G$30,MATCH($C14,Допущения!$B$25:$B$30,0),5))} -> 240000 | J14: =SUM(E14:I14) -> 424800 | L14: Серверы для параллельных вычислений (для обучения ML и ИИ) - у Раджеша были требования по ИИ => мы их минимально учли на будущее
B15: Итого по блоку | E15: =SUM(E7:E14) -> 26400 | F15: =SUM(F7:F14) -> 143760 | G15: =SUM(G7:G14) -> 471763.2 | H15: =SUM(H7:H14) -> 1174214.8 | I15: =SUM(I7:I14) -> 2344720.6 | J15: =SUM(J7:J14) -> 4160858.5 | K15: =IFERROR(J15/$J$50,0) -> 0.032063286
B17: БЛОК 2. Лицензии, SaaS и инструменты
B18: Observability (метрики, логи, трейсинг) | C18: пользователи | D18: 1200 | E18: {=IF($D18="","",$D18*INDEX(Допущения!$C$25:$G$30,MATCH($C18,Допущения!$B$25:$B$30,0),1))} -> 1200 | F18: {=IF($D18="","",$D18*INDEX(Допущения!$C$25:$G$30,MATCH($C18,Допущения!$B$25:$B$30,0),2))} -> 7200 | G18: {=IF($D18="","",$D18*INDEX(Допущения!$C$25:$G$30,MATCH($C18,Допущения!$B$25:$B$30,0),3))} -> 24000 | H18: {=IF($D18="","",$D18*INDEX(Допущения!$C$25:$G$30,MATCH($C18,Допущения!$B$25:$B$30,0),4))} -> 60000 | I18: {=IF($D18="","",$D18*INDEX(Допущения!$C$25:$G$30,MATCH($C18,Допущения!$B$25:$B$30,0),5))} -> 120000 | J18: =SUM(E18:I18) -> 212400 | L18: Объём логов растёт с нагрузкой
B19: CI/CD, репозиторий, артефакты | C19: инфляция | D19: 1200 | E19: {=IF($D19="","",$D19*INDEX(Допущения!$C$25:$G$30,MATCH($C19,Допущения!$B$25:$B$30,0),1))} -> 1200 | F19: {=IF($D19="","",$D19*INDEX(Допущения!$C$25:$G$30,MATCH($C19,Допущения!$B$25:$B$30,0),2))} -> 1344 | G19: {=IF($D19="","",$D19*INDEX(Допущения!$C$25:$G$30,MATCH($C19,Допущения!$B$25:$B$30,0),3))} -> 1505.28 | H19: {=IF($D19="","",$D19*INDEX(Допущения!$C$25:$G$30,MATCH($C19,Допущения!$B$25:$B$30,0),4))} -> 1685.9136 | I19: {=IF($D19="","",$D19*INDEX(Допущения!$C$25:$G$30,MATCH($C19,Допущения!$B$25:$B$30,0),5))} -> 1888.2232 | J19: =SUM(E19:I19) -> 7623.4168 | L19: GitHub / GitLab, тарифы на команду
B20: Безопасность: WAF, секреты, антифрод | C20: пользователи | D20: 1800 | E20: {=IF($D20="","",$D20*INDEX(Допущения!$C$25:$G$30,MATCH($C20,Допущения!$B$25:$B$30,0),1))} -> 1800 | F20: {=IF($D20="","",$D20*INDEX(Допущения!$C$25:$G$30,MATCH($C20,Допущения!$B$25:$B$30,0),2))} -> 10800 | G20: {=IF($D20="","",$D20*INDEX(Допущения!$C$25:$G$30,MATCH($C20,Допущения!$B$25:$B$30,0),3))} -> 36000 | H20: {=IF($D20="","",$D20*INDEX(Допущения!$C$25:$G$30,MATCH($C20,Допущения!$B$25:$B$30,0),4))} -> 90000 | I20: {=IF($D20="","",$D20*INDEX(Допущения!$C$25:$G$30,MATCH($C20,Допущения!$B$25:$B$30,0),5))} -> 180000 | J20: =SUM(E20:I20) -> 318600 | L20: Мошенничество на ПВЗ — риск из кейса
B21: WhatsApp Business API (подписка) | C21: инфляция | D21: 2400 | E21: {=IF($D21="","",$D21*INDEX(Допущения!$C$25:$G$30,MATCH($C21,Допущения!$B$25:$B$30,0),1))} -> 2400 | F21: {=IF($D21="","",$D21*INDEX(Допущения!$C$25:$G$30,MATCH($C21,Допущения!$B$25:$B$30,0),2))} -> 2688 | G21: {=IF($D21="","",$D21*INDEX(Допущения!$C$25:$G$30,MATCH($C21,Допущения!$B$25:$B$30,0),3))} -> 3010.56 | H21: {=IF($D21="","",$D21*INDEX(Допущения!$C$25:$G$30,MATCH($C21,Допущения!$B$25:$B$30,0),4))} -> 3371.8272 | I21: {=IF($D21="","",$D21*INDEX(Допущения!$C$25:$G$30,MATCH($C21,Допущения!$B$25:$B$30,0),5))} -> 3776.4465 | J21: =SUM(E21:I21) -> 15246.834 | L21: Канал для продавцов без личного кабинета
B22: Прочее ПО и подписки | C22: инфляция | D22: 1200 | E22: {=IF($D22="","",$D22*INDEX(Допущения!$C$25:$G$30,MATCH($C22,Допущения!$B$25:$B$30,0),1))} -> 1200 | F22: {=IF($D22="","",$D22*INDEX(Допущения!$C$25:$G$30,MATCH($C22,Допущения!$B$25:$B$30,0),2))} -> 1344 | G22: {=IF($D22="","",$D22*INDEX(Допущения!$C$25:$G$30,MATCH($C22,Допущения!$B$25:$B$30,0),3))} -> 1505.28 | H22: {=IF($D22="","",$D22*INDEX(Допущения!$C$25:$G$30,MATCH($C22,Допущения!$B$25:$B$30,0),4))} -> 1685.9136 | I22: {=IF($D22="","",$D22*INDEX(Допущения!$C$25:$G$30,MATCH($C22,Допущения!$B$25:$B$30,0),5))} -> 1888.2232 | J22: =SUM(E22:I22) -> 7623.4168 | L22: Таск-трекер, дизайн, аналитика
B23: Sentry | C23: пользователи | D23: 600 | E23: {=IF($D23="","",$D23*INDEX(Допущения!$C$25:$G$30,MATCH($C23,Допущения!$B$25:$B$30,0),1))} -> 600 | F23: {=IF($D23="","",$D23*INDEX(Допущения!$C$25:$G$30,MATCH($C23,Допущения!$B$25:$B$30,0),2))} -> 3600 | G23: {=IF($D23="","",$D23*INDEX(Допущения!$C$25:$G$30,MATCH($C23,Допущения!$B$25:$B$30,0),3))} -> 12000 | H23: {=IF($D23="","",$D23*INDEX(Допущения!$C$25:$G$30,MATCH($C23,Допущения!$B$25:$B$30,0),4))} -> 30000 | I23: {=IF($D23="","",$D23*INDEX(Допущения!$C$25:$G$30,MATCH($C23,Допущения!$B$25:$B$30,0),5))} -> 60000 | J23: =SUM(E23:I23) -> 106200 | L23: Error tracking - находит и подсвечивает ошибки (не нужно вручную просматривать все логи)
B24: Итого по блоку | E24: =SUM(E18:E23) -> 8400 | F24: =SUM(F18:F23) -> 26976 | G24: =SUM(G18:G23) -> 78021.12 | H24: =SUM(H18:H23) -> 186743.65 | I24: =SUM(I18:I23) -> 367552.89 | J24: =SUM(J18:J23) -> 667693.67 | K24: =IFERROR(J24/$J$50,0) -> 0.0051452009
B26: БЛОК 3. Транзакционные расходы (Buy / Partner)
B27: Комиссии платёжных провайдеров | C27: GMV | D27: 375000 | E27: {=IF($D27="","",$D27*INDEX(Допущения!$C$25:$G$30,MATCH($C27,Допущения!$B$25:$B$30,0),1))} -> 375000 | F27: {=IF($D27="","",$D27*INDEX(Допущения!$C$25:$G$30,MATCH($C27,Допущения!$B$25:$B$30,0),2))} -> 2340000 | G27: {=IF($D27="","",$D27*INDEX(Допущения!$C$25:$G$30,MATCH($C27,Допущения!$B$25:$B$30,0),3))} -> 8100000 | H27: {=IF($D27="","",$D27*INDEX(Допущения!$C$25:$G$30,MATCH($C27,Допущения!$B$25:$B$30,0),4))} -> 21000000 | I27: {=IF($D27="","",$D27*INDEX(Допущения!$C$25:$G$30,MATCH($C27,Допущения!$B$25:$B$30,0),5))} -> 43500000 | J27: =SUM(E27:I27) -> 75315000 | L27: ≈3% от GMV: M-Pesa (Кения), Flutterwave / Paystack (Нигерия)
B28: SMS-уведомления | C28: заказы | D28: 24000 | E28: {=IF($D28="","",$D28*INDEX(Допущения!$C$25:$G$30,MATCH($C28,Допущения!$B$25:$B$30,0),1))} -> 24000 | F28: {=IF($D28="","",$D28*INDEX(Допущения!$C$25:$G$30,MATCH($C28,Допущения!$B$25:$B$30,0),2))} -> 144000 | G28: {=IF($D28="","",$D28*INDEX(Допущения!$C$25:$G$30,MATCH($C28,Допущения!$B$25:$B$30,0),3))} -> 480000 | H28: {=IF($D28="","",$D28*INDEX(Допущения!$C$25:$G$30,MATCH($C28,Допущения!$B$25:$B$30,0),4))} -> 1200000 | I28: {=IF($D28="","",$D28*INDEX(Допущения!$C$25:$G$30,MATCH($C28,Допущения!$B$25:$B$30,0),5))} -> 2400000 | J28: =SUM(E28:I28) -> 4248000 | L28: ≈$0,04 за SMS × заказы
B29: WhatsApp-сообщения (за диалог) | C29: заказы | D29: 18000 | E29: {=IF($D29="","",$D29*INDEX(Допущения!$C$25:$G$30,MATCH($C29,Допущения!$B$25:$B$30,0),1))} -> 18000 | F29: {=IF($D29="","",$D29*INDEX(Допущения!$C$25:$G$30,MATCH($C29,Допущения!$B$25:$B$30,0),2))} -> 108000 | G29: {=IF($D29="","",$D29*INDEX(Допущения!$C$25:$G$30,MATCH($C29,Допущения!$B$25:$B$30,0),3))} -> 360000 | H29: {=IF($D29="","",$D29*INDEX(Допущения!$C$25:$G$30,MATCH($C29,Допущения!$B$25:$B$30,0),4))} -> 900000 | I29: {=IF($D29="","",$D29*INDEX(Допущения!$C$25:$G$30,MATCH($C29,Допущения!$B$25:$B$30,0),5))} -> 1800000 | J29: =SUM(E29:I29) -> 3186000 | L29: Тариф Meta за conversation
B30: Логистика: интеграции и комиссии партнёров | C30: заказы | D30: 90000 | E30: {=IF($D30="","",$D30*INDEX(Допущения!$C$25:$G$30,MATCH($C30,Допущения!$B$25:$B$30,0),1))} -> 90000 | F30: {=IF($D30="","",$D30*INDEX(Допущения!$C$25:$G$30,MATCH($C30,Допущения!$B$25:$B$30,0),2))} -> 540000 | G30: {=IF($D30="","",$D30*INDEX(Допущения!$C$25:$G$30,MATCH($C30,Допущения!$B$25:$B$30,0),3))} -> 1800000 | H30: {=IF($D30="","",$D30*INDEX(Допущения!$C$25:$G$30,MATCH($C30,Допущения!$B$25:$B$30,0),4))} -> 4500000 | I30: {=IF($D30="","",$D30*INDEX(Допущения!$C$25:$G$30,MATCH($C30,Допущения!$B$25:$B$30,0),5))} -> 9000000 | J30: =SUM(E30:I30) -> 15930000 | L30: Sendbox (Нигерия), Sendy (Кения)
B31: Выплаты продавцам | C31: заказы | D31: 12000 | E31: {=IF($D31="","",$D31*INDEX(Допущения!$C$25:$G$30,MATCH($C31,Допущения!$B$25:$B$30,0),1))} -> 12000 | F31: {=IF($D31="","",$D31*INDEX(Допущения!$C$25:$G$30,MATCH($C31,Допущения!$B$25:$B$30,0),2))} -> 72000 | G31: {=IF($D31="","",$D31*INDEX(Допущения!$C$25:$G$30,MATCH($C31,Допущения!$B$25:$B$30,0),3))} -> 240000 | H31: {=IF($D31="","",$D31*INDEX(Допущения!$C$25:$G$30,MATCH($C31,Допущения!$B$25:$B$30,0),4))} -> 600000 | I31: {=IF($D31="","",$D31*INDEX(Допущения!$C$25:$G$30,MATCH($C31,Допущения!$B$25:$B$30,0),5))} -> 1200000 | J31: =SUM(E31:I31) -> 2124000 | L31: Выплаты продавцам T+1: $0,02/заказ × 600k = $12 000/год. M-Pesa B2C: 0,3% от суммы; Flutterwave Payouts: 1%. Средневзвешенно — $0,02/заказ.
B32: Итого по блоку | E32: =SUM(E27:E31) -> 519000 | F32: =SUM(F27:F31) -> 3204000 | G32: =SUM(G27:G31) -> 10980000 | H32: =SUM(H27:H31) -> 28200000 | I32: =SUM(I27:I31) -> 57900000 | J32: =SUM(J27:J31) -> 100803000 | K32: =IFERROR(J32/$J$50,0) -> 0.7767809
B34: БЛОК 4. Команда (ФОТ)
B35: Разработка (FTE × годовая ставка) | C35: ФОТ | D35: 240000 | E35: {=IF($D35="","",$D35*INDEX(Допущения!$C$25:$G$30,MATCH($C35,Допущения!$B$25:$B$30,0),1))} -> 240000 | F35: {=IF($D35="","",$D35*INDEX(Допущения!$C$25:$G$30,MATCH($C35,Допущения!$B$25:$B$30,0),2))} -> 259200 | G35: {=IF($D35="","",$D35*INDEX(Допущения!$C$25:$G$30,MATCH($C35,Допущения!$B$25:$B$30,0),3))} -> 279936 | H35: {=IF($D35="","",$D35*INDEX(Допущения!$C$25:$G$30,MATCH($C35,Допущения!$B$25:$B$30,0),4))} -> 302330.88 | I35: {=IF($D35="","",$D35*INDEX(Допущения!$C$25:$G$30,MATCH($C35,Допущения!$B$25:$B$30,0),5))} -> 326517.35 | J35: =SUM(E35:I35) -> 1407984.2 | L35: Например 6 FTE × $60k. Зависит от арх. варианта!
B36: DevOps / SRE | C36: ФОТ | D36: 70000 | E36: {=IF($D36="","",$D36*INDEX(Допущения!$C$25:$G$30,MATCH($C36,Допущения!$B$25:$B$30,0),1))} -> 70000 | F36: {=IF($D36="","",$D36*INDEX(Допущения!$C$25:$G$30,MATCH($C36,Допущения!$B$25:$B$30,0),2))} -> 75600 | G36: {=IF($D36="","",$D36*INDEX(Допущения!$C$25:$G$30,MATCH($C36,Допущения!$B$25:$B$30,0),3))} -> 81648 | H36: {=IF($D36="","",$D36*INDEX(Допущения!$C$25:$G$30,MATCH($C36,Допущения!$B$25:$B$30,0),4))} -> 88179.84 | I36: {=IF($D36="","",$D36*INDEX(Допущения!$C$25:$G$30,MATCH($C36,Допущения!$B$25:$B$30,0),5))} -> 95234.227 | J36: =SUM(E36:I36) -> 410662.07 | L36: Микросервисы требуют больше SRE, чем монолит
B37: Поддержка и дежурства 24/7 | C37: ФОТ | D37: 0 | E37: {=IF($D37="","",$D37*INDEX(Допущения!$C$25:$G$30,MATCH($C37,Допущения!$B$25:$B$30,0),1))} -> 0 | F37: {=IF($D37="","",$D37*INDEX(Допущения!$C$25:$G$30,MATCH($C37,Допущения!$B$25:$B$30,0),2))} -> 0 | G37: {=IF($D37="","",$D37*INDEX(Допущения!$C$25:$G$30,MATCH($C37,Допущения!$B$25:$B$30,0),3))} -> 0 | H37: {=IF($D37="","",$D37*INDEX(Допущения!$C$25:$G$30,MATCH($C37,Допущения!$B$25:$B$30,0),4))} -> 0 | I37: {=IF($D37="","",$D37*INDEX(Допущения!$C$25:$G$30,MATCH($C37,Допущения!$B$25:$B$30,0),5))} -> 0 | J37: =SUM(E37:I37) -> 0 | L37: Время разработчиков => входит в их зп
B38: Архитектура и менеджмент | C38: ФОТ | D38: 60000 | E38: {=IF($D38="","",$D38*INDEX(Допущения!$C$25:$G$30,MATCH($C38,Допущения!$B$25:$B$30,0),1))} -> 60000 | F38: {=IF($D38="","",$D38*INDEX(Допущения!$C$25:$G$30,MATCH($C38,Допущения!$B$25:$B$30,0),2))} -> 64800 | G38: {=IF($D38="","",$D38*INDEX(Допущения!$C$25:$G$30,MATCH($C38,Допущения!$B$25:$B$30,0),3))} -> 69984 | H38: {=IF($D38="","",$D38*INDEX(Допущения!$C$25:$G$30,MATCH($C38,Допущения!$B$25:$B$30,0),4))} -> 75582.72 | I38: {=IF($D38="","",$D38*INDEX(Допущения!$C$25:$G$30,MATCH($C38,Допущения!$B$25:$B$30,0),5))} -> 81629.338 | J38: =SUM(E38:I38) -> 351996.06 | L38: Solution Architect, CTO-функция, PM
B39: Итого по блоку | E39: =SUM(E35:E38) -> 370000 | F39: =SUM(F35:F38) -> 399600 | G39: =SUM(G35:G38) -> 431568 | H39: =SUM(H35:H38) -> 466093.44 | I39: =SUM(I35:I38) -> 503380.92 | J39: =SUM(J35:J38) -> 2170642.4 | K39: =IFERROR(J39/$J$50,0) -> 0.016726819
B41: БЛОК 5. Разовые затраты и комплаенс
B42: Юридический и комплаенс-аудит (NDPR, POPIA, KICA) | C42: фикс | D42: 25000 | E42: {=IF($D42="","",$D42*INDEX(Допущения!$C$25:$G$30,MATCH($C42,Допущения!$B$25:$B$30,0),1))} -> 25000 | F42: {=IF($D42="","",$D42*INDEX(Допущения!$C$25:$G$30,MATCH($C42,Допущения!$B$25:$B$30,0),2))} -> 25000 | G42: {=IF($D42="","",$D42*INDEX(Допущения!$C$25:$G$30,MATCH($C42,Допущения!$B$25:$B$30,0),3))} -> 25000 | H42: {=IF($D42="","",$D42*INDEX(Допущения!$C$25:$G$30,MATCH($C42,Допущения!$B$25:$B$30,0),4))} -> 25000 | I42: {=IF($D42="","",$D42*INDEX(Допущения!$C$25:$G$30,MATCH($C42,Допущения!$B$25:$B$30,0),5))} -> 25000 | J42: =SUM(E42:I42) -> 125000 | L42: Разовая статья — обнули лишние годы вручную
B43: Пентест и аудит безопасности | C43: инфляция | D43: 15000 | E43: {=IF($D43="","",$D43*INDEX(Допущения!$C$25:$G$30,MATCH($C43,Допущения!$B$25:$B$30,0),1))} -> 15000 | F43: {=IF($D43="","",$D43*INDEX(Допущения!$C$25:$G$30,MATCH($C43,Допущения!$B$25:$B$30,0),2))} -> 16800 | G43: {=IF($D43="","",$D43*INDEX(Допущения!$C$25:$G$30,MATCH($C43,Допущения!$B$25:$B$30,0),3))} -> 18816 | H43: {=IF($D43="","",$D43*INDEX(Допущения!$C$25:$G$30,MATCH($C43,Допущения!$B$25:$B$30,0),4))} -> 21073.92 | I43: {=IF($D43="","",$D43*INDEX(Допущения!$C$25:$G$30,MATCH($C43,Допущения!$B$25:$B$30,0),5))} -> 23602.79 | J43: =SUM(E43:I43) -> 95292.71 | L43: Ежегодно, если mission critical
B44: Миграция данных и интеграции при запуске | C44: фикс | D44: 10000 | E44: {=IF($D44="","",$D44*INDEX(Допущения!$C$25:$G$30,MATCH($C44,Допущения!$B$25:$B$30,0),1))} -> 10000 | F44: {=IF($D44="","",$D44*INDEX(Допущения!$C$25:$G$30,MATCH($C44,Допущения!$B$25:$B$30,0),2))} -> 10000 | G44: {=IF($D44="","",$D44*INDEX(Допущения!$C$25:$G$30,MATCH($C44,Допущения!$B$25:$B$30,0),3))} -> 10000 | H44: {=IF($D44="","",$D44*INDEX(Допущения!$C$25:$G$30,MATCH($C44,Допущения!$B$25:$B$30,0),4))} -> 10000 | I44: {=IF($D44="","",$D44*INDEX(Допущения!$C$25:$G$30,MATCH($C44,Допущения!$B$25:$B$30,0),5))} -> 10000 | J44: =SUM(E44:I44) -> 50000 | L44: Разовая статья
B45: Обучение команды и найм | C45: ФОТ | D45: 5000 | E45: {=IF($D45="","",$D45*INDEX(Допущения!$C$25:$G$30,MATCH($C45,Допущения!$B$25:$B$30,0),1))} -> 5000 | F45: {=IF($D45="","",$D45*INDEX(Допущения!$C$25:$G$30,MATCH($C45,Допущения!$B$25:$B$30,0),2))} -> 5400 | G45: {=IF($D45="","",$D45*INDEX(Допущения!$C$25:$G$30,MATCH($C45,Допущения!$B$25:$B$30,0),3))} -> 5832 | H45: {=IF($D45="","",$D45*INDEX(Допущения!$C$25:$G$30,MATCH($C45,Допущения!$B$25:$B$30,0),4))} -> 6298.56 | I45: {=IF($D45="","",$D45*INDEX(Допущения!$C$25:$G$30,MATCH($C45,Допущения!$B$25:$B$30,0),5))} -> 6802.4448 | J45: =SUM(E45:I45) -> 29333.005 | L45: Дефицит локальных ИТ-специалистов
B46: Регистрация юридического лица и местный комплаенс (Нигерия + Кения) | C46: фикс | D46: 8000 | E46: {=IF($D46="","",$D46*INDEX(Допущения!$C$25:$G$30,MATCH($C46,Допущения!$B$25:$B$30,0),1))} -> 8000 | F46: {=IF($D46="","",$D46*INDEX(Допущения!$C$25:$G$30,MATCH($C46,Допущения!$B$25:$B$30,0),2))} -> 8000 | G46: {=IF($D46="","",$D46*INDEX(Допущения!$C$25:$G$30,MATCH($C46,Допущения!$B$25:$B$30,0),3))} -> 8000 | H46: {=IF($D46="","",$D46*INDEX(Допущения!$C$25:$G$30,MATCH($C46,Допущения!$B$25:$B$30,0),4))} -> 8000 | I46: {=IF($D46="","",$D46*INDEX(Допущения!$C$25:$G$30,MATCH($C46,Допущения!$B$25:$B$30,0),5))} -> 8000 | J46: =SUM(E46:I46) -> 40000 | L46: Регистрация компании в двух юрисдикциях: $4 000 на страну (регистрация, лицензии на маркетплейс, местный юрист). Разовые затраты на вхождение в рынок.
...

Sheet TCO МС
B2: TCO на 5 лет — Africa Delivery
B3: Заполняем колонки «Драйвер роста» и «База, $/год (Год 1)». Годы 1–5 считаются автоматически.
B5: Статья затрат | C5: Драйвер роста | D5: База, $/год (Год 1) | E5: Год 1 | F5: Год 2 | G5: Год 3 | H5: Год 4 | I5: Год 5 | J5: Итого 5 лет | K5: Доля | L5: Комментарий / источник
B6: БЛОК 1. Облачная инфраструктура (OpEx)
B7: Compute: ноды / контейнеры / serverless | C7: пользователи | D7: 36000 | E7: {=IF($D7="","",$D7*INDEX(Допущения!$C$25:$G$30,MATCH($C7,Допущения!$B$25:$B$30,0),1))} -> 36000 | F7: {=IF($D7="","",$D7*INDEX(Допущения!$C$25:$G$30,MATCH($C7,Допущения!$B$25:$B$30,0),2))} -> 216000 | G7: {=IF($D7="","",$D7*INDEX(Допущения!$C$25:$G$30,MATCH($C7,Допущения!$B$25:$B$30,0),3))} -> 720000 | H7: {=IF($D7="","",$D7*INDEX(Допущения!$C$25:$G$30,MATCH($C7,Допущения!$B$25:$B$30,0),4))} -> 1800000 | I7: {=IF($D7="","",$D7*INDEX(Допущения!$C$25:$G$30,MATCH($C7,Допущения!$B$25:$B$30,0),5))} -> 3600000 | J7: =SUM(E7:I7) -> 6372000 | L7: AWS af-south-1, оценка по калькулятору
B8: Управляемые БД (PostgreSQL, реплики) | C8: пользователи | D8: 12000 | E8: {=IF($D8="","",$D8*INDEX(Допущения!$C$25:$G$30,MATCH($C8,Допущения!$B$25:$B$30,0),1))} -> 12000 | F8: {=IF($D8="","",$D8*INDEX(Допущения!$C$25:$G$30,MATCH($C8,Допущения!$B$25:$B$30,0),2))} -> 72000 | G8: {=IF($D8="","",$D8*INDEX(Допущения!$C$25:$G$30,MATCH($C8,Допущения!$B$25:$B$30,0),3))} -> 240000 | H8: {=IF($D8="","",$D8*INDEX(Допущения!$C$25:$G$30,MATCH($C8,Допущения!$B$25:$B$30,0),4))} -> 600000 | I8: {=IF($D8="","",$D8*INDEX(Допущения!$C$25:$G$30,MATCH($C8,Допущения!$B$25:$B$30,0),5))} -> 1200000 | J8: =SUM(E8:I8) -> 2124000 | L8: Managed RDS + read replica
B9: Хранилище объектов и резервные копии | C9: пользователи | D9: 6000 | E9: {=IF($D9="","",$D9*INDEX(Допущения!$C$25:$G$30,MATCH($C9,Допущения!$B$25:$B$30,0),1))} -> 6000 | F9: {=IF($D9="","",$D9*INDEX(Допущения!$C$25:$G$30,MATCH($C9,Допущения!$B$25:$B$30,0),2))} -> 36000 | G9: {=IF($D9="","",$D9*INDEX(Допущения!$C$25:$G$30,MATCH($C9,Допущения!$B$25:$B$30,0),3))} -> 120000 | H9: {=IF($D9="","",$D9*INDEX(Допущения!$C$25:$G$30,MATCH($C9,Допущения!$B$25:$B$30,0),4))} -> 300000 | I9: {=IF($D9="","",$D9*INDEX(Допущения!$C$25:$G$30,MATCH($C9,Допущения!$B$25:$B$30,0),5))} -> 600000 | J9: =SUM(E9:I9) -> 1062000 | L9: Фото товаров, 5000 SKU на старте
B10: CDN и исходящий трафик | C10: пользователи | D10: 12000 | E10: {=IF($D10="","",$D10*INDEX(Допущения!$C$25:$G$30,MATCH($C10,Допущения!$B$25:$B$30,0),1))} -> 12000 | F10: {=IF($D10="","",$D10*INDEX(Допущения!$C$25:$G$30,MATCH($C10,Допущения!$B$25:$B$30,0),2))} -> 72000 | G10: {=IF($D10="","",$D10*INDEX(Допущения!$C$25:$G$30,MATCH($C10,Допущения!$B$25:$B$30,0),3))} -> 240000 | H10: {=IF($D10="","",$D10*INDEX(Допущения!$C$25:$G$30,MATCH($C10,Допущения!$B$25:$B$30,0),4))} -> 600000 | I10: {=IF($D10="","",$D10*INDEX(Допущения!$C$25:$G$30,MATCH($C10,Допущения!$B$25:$B$30,0),5))} -> 1200000 | J10: =SUM(E10:I10) -> 2124000 | L10: 70% трафика — мобильный 3G, картинки WebP
B11: Очереди / стриминг (Kafka, SQS) | C11: пользователи | D11: 6000 | E11: {=IF($D11="","",$D11*INDEX(Допущения!$C$25:$G$30,MATCH($C11,Допущения!$B$25:$B$30,0),1))} -> 6000 | F11: {=IF($D11="","",$D11*INDEX(Допущения!$C$25:$G$30,MATCH($C11,Допущения!$B$25:$B$30,0),2))} -> 36000 | G11: {=IF($D11="","",$D11*INDEX(Допущения!$C$25:$G$30,MATCH($C11,Допущения!$B$25:$B$30,0),3))} -> 120000 | H11: {=IF($D11="","",$D11*INDEX(Допущения!$C$25:$G$30,MATCH($C11,Допущения!$B$25:$B$30,0),4))} -> 300000 | I11: {=IF($D11="","",$D11*INDEX(Допущения!$C$25:$G$30,MATCH($C11,Допущения!$B$25:$B$30,0),5))} -> 600000 | J11: =SUM(E11:I11) -> 1062000 | L11: Асинхронные заказы и уведомления
B12: Резервный регион / DR | C12: пользователи | D12: 12000 | E12: {=IF($D12="","",$D12*INDEX(Допущения!$C$25:$G$30,MATCH($C12,Допущения!$B$25:$B$30,0),1))} -> 12000 | F12: {=IF($D12="","",$D12*INDEX(Допущения!$C$25:$G$30,MATCH($C12,Допущения!$B$25:$B$30,0),2))} -> 72000 | G12: {=IF($D12="","",$D12*INDEX(Допущения!$C$25:$G$30,MATCH($C12,Допущения!$B$25:$B$30,0),3))} -> 240000 | H12: {=IF($D12="","",$D12*INDEX(Допущения!$C$25:$G$30,MATCH($C12,Допущения!$B$25:$B$30,0),4))} -> 600000 | I12: {=IF($D12="","",$D12*INDEX(Допущения!$C$25:$G$30,MATCH($C12,Допущения!$B$25:$B$30,0),5))} -> 1200000 | J12: =SUM(E12:I12) -> 2124000 | L12: Зависит от выбранной стратегии RTO/RPO
B13: Локальное размещение данных (NDPR, Нигерия) | C13: инфляция | D13: 3000 | E13: {=IF($D13="","",$D13*INDEX(Допущения!$C$25:$G$30,MATCH($C13,Допущения!$B$25:$B$30,0),1))} -> 3000 | F13: =IF($D13="","",$D13*INDEX(Допущения!$C$25:$G$30,MATCH($C13,Допущения!$B$25:$B$30,0),2)) -> 3360 | G13: {=IF($D13="","",$D13*INDEX(Допущения!$C$25:$G$30,MATCH($C13,Допущения!$B$25:$B$30,0),3))} -> 3763.2 | H13: {=IF($D13="","",$D13*INDEX(Допущения!$C$25:$G$30,MATCH($C13,Допущения!$B$25:$B$30,0),4))} -> 4214.784 | I13: {=IF($D13="","",$D13*INDEX(Допущения!$C$25:$G$30,MATCH($C13,Допущения!$B$25:$B$30,0),5))} -> 4720.5581 | J13: =SUM(E13:I13) -> 19058.542 | L13: Локальный провайдер или партнёр — см. ADR №3
B14: Service Mesh (Istio) | C14: пользователи | D14: 6000 | E14: {=IF($D14="","",$D14*INDEX(Допущения!$C$25:$G$30,MATCH($C14,Допущения!$B$25:$B$30,0),1))} -> 6000 | F14: {=IF($D14="","",$D14*INDEX(Допущения!$C$25:$G$30,MATCH($C14,Допущения!$B$25:$B$30,0),2))} -> 36000 | G14: {=IF($D14="","",$D14*INDEX(Допущения!$C$25:$G$30,MATCH($C14,Допущения!$B$25:$B$30,0),3))} -> 120000 | H14: {=IF($D14="","",$D14*INDEX(Допущения!$C$25:$G$30,MATCH($C14,Допущения!$B$25:$B$30,0),4))} -> 300000 | I14: {=IF($D14="","",$D14*INDEX(Допущения!$C$25:$G$30,MATCH($C14,Допущения!$B$25:$B$30,0),5))} -> 600000 | J14: =SUM(E14:I14) -> 1062000 | L14: Обрабатывают весь трафик пользователей. Ресурсы на них растут пропорционально числу пользователей: $500/мес на старте (6 нод × 50 подов). Источник: оценка по GKE/EKS pricing + 15% на sidecar-оверхед.
B15: Итого по блоку | E15: =SUM(E7:E14) -> 93000 | F15: =SUM(F7:F14) -> 543360 | G15: =SUM(G7:G14) -> 1803763.2 | H15: =SUM(H7:H14) -> 4504214.8 | I15: =SUM(I7:I14) -> 9004720.6 | J15: =SUM(J7:J14) -> 15949059 | K15: =IFERROR(J15/$J$50,0) -> 0.10580611
B17: БЛОК 2. Лицензии, SaaS и инструменты
B18: Observability (метрики, логи, трейсинг) | C18: пользователи | D18: 6000 | E18: {=IF($D18="","",$D18*INDEX(Допущения!$C$25:$G$30,MATCH($C18,Допущения!$B$25:$B$30,0),1))} -> 6000 | F18: {=IF($D18="","",$D18*INDEX(Допущения!$C$25:$G$30,MATCH($C18,Допущения!$B$25:$B$30,0),2))} -> 36000 | G18: {=IF($D18="","",$D18*INDEX(Допущения!$C$25:$G$30,MATCH($C18,Допущения!$B$25:$B$30,0),3))} -> 120000 | H18: {=IF($D18="","",$D18*INDEX(Допущения!$C$25:$G$30,MATCH($C18,Допущения!$B$25:$B$30,0),4))} -> 300000 | I18: {=IF($D18="","",$D18*INDEX(Допущения!$C$25:$G$30,MATCH($C18,Допущения!$B$25:$B$30,0),5))} -> 600000 | J18: =SUM(E18:I18) -> 1062000 | L18: Объём логов растёт с нагрузкой
B19: CI/CD, репозиторий, артефакты | C19: инфляция | D19: 3600 | E19: {=IF($D19="","",$D19*INDEX(Допущения!$C$25:$G$30,MATCH($C19,Допущения!$B$25:$B$30,0),1))} -> 3600 | F19: {=IF($D19="","",$D19*INDEX(Допущения!$C$25:$G$30,MATCH($C19,Допущения!$B$25:$B$30,0),2))} -> 4032 | G19: {=IF($D19="","",$D19*INDEX(Допущения!$C$25:$G$30,MATCH($C19,Допущения!$B$25:$B$30,0),3))} -> 4515.84 | H19: {=IF($D19="","",$D19*INDEX(Допущения!$C$25:$G$30,MATCH($C19,Допущения!$B$25:$B$30,0),4))} -> 5057.7408 | I19: {=IF($D19="","",$D19*INDEX(Допущения!$C$25:$G$30,MATCH($C19,Допущения!$B$25:$B$30,0),5))} -> 5664.6697 | J19: =SUM(E19:I19) -> 22870.25 | L19: GitHub / GitLab, тарифы на команду
B20: Безопасность: WAF, секреты, антифрод | C20: пользователи | D20: 4800 | E20: {=IF($D20="","",$D20*INDEX(Допущения!$C$25:$G$30,MATCH($C20,Допущения!$B$25:$B$30,0),1))} -> 4800 | F20: {=IF($D20="","",$D20*INDEX(Допущения!$C$25:$G$30,MATCH($C20,Допущения!$B$25:$B$30,0),2))} -> 28800 | G20: {=IF($D20="","",$D20*INDEX(Допущения!$C$25:$G$30,MATCH($C20,Допущения!$B$25:$B$30,0),3))} -> 96000 | H20: {=IF($D20="","",$D20*INDEX(Допущения!$C$25:$G$30,MATCH($C20,Допущения!$B$25:$B$30,0),4))} -> 240000 | I20: {=IF($D20="","",$D20*INDEX(Допущения!$C$25:$G$30,MATCH($C20,Допущения!$B$25:$B$30,0),5))} -> 480000 | J20: =SUM(E20:I20) -> 849600 | L20: Мошенничество на ПВЗ — риск из кейса
B21: WhatsApp Business API (подписка) | C21: инфляция | D21: 2400 | E21: {=IF($D21="","",$D21*INDEX(Допущения!$C$25:$G$30,MATCH($C21,Допущения!$B$25:$B$30,0),1))} -> 2400 | F21: {=IF($D21="","",$D21*INDEX(Допущения!$C$25:$G$30,MATCH($C21,Допущения!$B$25:$B$30,0),2))} -> 2688 | G21: {=IF($D21="","",$D21*INDEX(Допущения!$C$25:$G$30,MATCH($C21,Допущения!$B$25:$B$30,0),3))} -> 3010.56 | H21: {=IF($D21="","",$D21*INDEX(Допущения!$C$25:$G$30,MATCH($C21,Допущения!$B$25:$B$30,0),4))} -> 3371.8272 | I21: {=IF($D21="","",$D21*INDEX(Допущения!$C$25:$G$30,MATCH($C21,Допущения!$B$25:$B$30,0),5))} -> 3776.4465 | J21: =SUM(E21:I21) -> 15246.834 | L21: Канал для продавцов без личного кабинета
B22: Прочее ПО и подписки | C22: инфляция | D22: 2400 | E22: {=IF($D22="","",$D22*INDEX(Допущения!$C$25:$G$30,MATCH($C22,Допущения!$B$25:$B$30,0),1))} -> 2400 | F22: {=IF($D22="","",$D22*INDEX(Допущения!$C$25:$G$30,MATCH($C22,Допущения!$B$25:$B$30,0),2))} -> 2688 | G22: {=IF($D22="","",$D22*INDEX(Допущения!$C$25:$G$30,MATCH($C22,Допущения!$B$25:$B$30,0),3))} -> 3010.56 | H22: {=IF($D22="","",$D22*INDEX(Допущения!$C$25:$G$30,MATCH($C22,Допущения!$B$25:$B$30,0),4))} -> 3371.8272 | I22: {=IF($D22="","",$D22*INDEX(Допущения!$C$25:$G$30,MATCH($C22,Допущения!$B$25:$B$30,0),5))} -> 3776.4465 | J22: =SUM(E22:I22) -> 15246.834 | L22: Таск-трекер, дизайн, аналитика
B23: API Gateway (Kong) | C23: пользователи | D23: 6000 | E23: {=IF($D23="","",$D23*INDEX(Допущения!$C$25:$G$30,MATCH($C23,Допущения!$B$25:$B$30,0),1))} -> 6000 | F23: {=IF($D23="","",$D23*INDEX(Допущения!$C$25:$G$30,MATCH($C23,Допущения!$B$25:$B$30,0),2))} -> 36000 | G23: {=IF($D23="","",$D23*INDEX(Допущения!$C$25:$G$30,MATCH($C23,Допущения!$B$25:$B$30,0),3))} -> 120000 | H23: {=IF($D23="","",$D23*INDEX(Допущения!$C$25:$G$30,MATCH($C23,Допущения!$B$25:$B$30,0),4))} -> 300000 | I23: {=IF($D23="","",$D23*INDEX(Допущения!$C$25:$G$30,MATCH($C23,Допущения!$B$25:$B$30,0),5))} -> 600000 | J23: =SUM(E23:I23) -> 1062000 | L23: Обрабатывает все входящие запросы пользователей, поэтому растёт с их числом. Источник: официальный прайс Kong, оценка по GCP/EKS pricing.
B24: Итого по блоку | E24: =SUM(E18:E23) -> 25200 | F24: =SUM(F18:F23) -> 110208 | G24: =SUM(G18:G23) -> 346536.96 | H24: =SUM(H18:H23) -> 851801.4 | I24: =SUM(I18:I23) -> 1693217.6 | J24: =SUM(J18:J23) -> 3026963.9 | K24: =IFERROR(J24/$J$50,0) -> 0.020080889
B26: БЛОК 3. Транзакционные расходы (Buy / Partner)
B27: Комиссии платёжных провайдеров | C27: GMV | D27: 375000 | E27: {=IF($D27="","",$D27*INDEX(Допущения!$C$25:$G$30,MATCH($C27,Допущения!$B$25:$B$30,0),1))} -> 375000 | F27: {=IF($D27="","",$D27*INDEX(Допущения!$C$25:$G$30,MATCH($C27,Допущения!$B$25:$B$30,0),2))} -> 2340000 | G27: {=IF($D27="","",$D27*INDEX(Допущения!$C$25:$G$30,MATCH($C27,Допущения!$B$25:$B$30,0),3))} -> 8100000 | H27: {=IF($D27="","",$D27*INDEX(Допущения!$C$25:$G$30,MATCH($C27,Допущения!$B$25:$B$30,0),4))} -> 21000000 | I27: {=IF($D27="","",$D27*INDEX(Допущения!$C$25:$G$30,MATCH($C27,Допущения!$B$25:$B$30,0),5))} -> 43500000 | J27: =SUM(E27:I27) -> 75315000 | L27: ≈3% от GMV: M-Pesa (Кения), Flutterwave / Paystack (Нигерия)
B28: SMS-уведомления | C28: заказы | D28: 24000 | E28: {=IF($D28="","",$D28*INDEX(Допущения!$C$25:$G$30,MATCH($C28,Допущения!$B$25:$B$30,0),1))} -> 24000 | F28: {=IF($D28="","",$D28*INDEX(Допущения!$C$25:$G$30,MATCH($C28,Допущения!$B$25:$B$30,0),2))} -> 144000 | G28: {=IF($D28="","",$D28*INDEX(Допущения!$C$25:$G$30,MATCH($C28,Допущения!$B$25:$B$30,0),3))} -> 480000 | H28: {=IF($D28="","",$D28*INDEX(Допущения!$C$25:$G$30,MATCH($C28,Допущения!$B$25:$B$30,0),4))} -> 1200000 | I28: {=IF($D28="","",$D28*INDEX(Допущения!$C$25:$G$30,MATCH($C28,Допущения!$B$25:$B$30,0),5))} -> 2400000 | J28: =SUM(E28:I28) -> 4248000 | L28: ≈$0,04 за SMS × заказы
B29: WhatsApp-сообщения (за диалог) | C29: заказы | D29: 18000 | E29: {=IF($D29="","",$D29*INDEX(Допущения!$C$25:$G$30,MATCH($C29,Допущения!$B$25:$B$30,0),1))} -> 18000 | F29: {=IF($D29="","",$D29*INDEX(Допущения!$C$25:$G$30,MATCH($C29,Допущения!$B$25:$B$30,0),2))} -> 108000 | G29: {=IF($D29="","",$D29*INDEX(Допущения!$C$25:$G$30,MATCH($C29,Допущения!$B$25:$B$30,0),3))} -> 360000 | H29: {=IF($D29="","",$D29*INDEX(Допущения!$C$25:$G$30,MATCH($C29,Допущения!$B$25:$B$30,0),4))} -> 900000 | I29: {=IF($D29="","",$D29*INDEX(Допущения!$C$25:$G$30,MATCH($C29,Допущения!$B$25:$B$30,0),5))} -> 1800000 | J29: =SUM(E29:I29) -> 3186000 | L29: Тариф Meta за conversation
B30: Логистика: интеграции и комиссии партнёров | C30: заказы | D30: 90000 | E30: {=IF($D30="","",$D30*INDEX(Допущения!$C$25:$G$30,MATCH($C30,Допущения!$B$25:$B$30,0),1))} -> 90000 | F30: {=IF($D30="","",$D30*INDEX(Допущения!$C$25:$G$30,MATCH($C30,Допущения!$B$25:$B$30,0),2))} -> 540000 | G30: {=IF($D30="","",$D30*INDEX(Допущения!$C$25:$G$30,MATCH($C30,Допущения!$B$25:$B$30,0),3))} -> 1800000 | H30: {=IF($D30="","",$D30*INDEX(Допущения!$C$25:$G$30,MATCH($C30,Допущения!$B$25:$B$30,0),4))} -> 4500000 | I30: {=IF($D30="","",$D30*INDEX(Допущения!$C$25:$G$30,MATCH($C30,Допущения!$B$25:$B$30,0),5))} -> 9000000 | J30: =SUM(E30:I30) -> 15930000 | L30: Sendbox (Нигерия), Sendy (Кения)
B31: Комиссия за выплаты продавцам (M-Pesa B2C / Flutterwave Payouts) | C31: заказы | D31: 12000 | E31: {=IF($D31="","",$D31*INDEX(Допущения!$C$25:$G$30,MATCH($C31,Допущения!$B$25:$B$30,0),1))} -> 12000 | F31: {=IF($D31="","",$D31*INDEX(Допущения!$C$25:$G$30,MATCH($C31,Допущения!$B$25:$B$30,0),2))} -> 72000 | G31: {=IF($D31="","",$D31*INDEX(Допущения!$C$25:$G$30,MATCH($C31,Допущения!$B$25:$B$30,0),3))} -> 240000 | H31: {=IF($D31="","",$D31*INDEX(Допущения!$C$25:$G$30,MATCH($C31,Допущения!$B$25:$B$30,0),4))} -> 600000 | I31: {=IF($D31="","",$D31*INDEX(Допущения!$C$25:$G$30,MATCH($C31,Допущения!$B$25:$B$30,0),5))} -> 1200000 | J31: =SUM(E31:I31) -> 2124000 | L31: Выплаты продавцам T+1: $0,02/заказ × 600k = $12 000/год. M-Pesa B2C: 0,3% от суммы; Flutterwave Payouts: 1%. Средневзвешенно — $0,02/заказ.
B32: Итого по блоку | E32: =SUM(E27:E31) -> 519000 | F32: =SUM(F27:F31) -> 3204000 | G32: =SUM(G27:G31) -> 10980000 | H32: =SUM(H27:H31) -> 28200000 | I32: =SUM(I27:I31) -> 57900000 | J32: =SUM(J27:J31) -> 100803000 | K32: =IFERROR(J32/$J$50,0) -> 0.66872743
B34: БЛОК 4. Команда (ФОТ)
B35: Разработка (FTE × годовая ставка) | C35: ФОТ | D35: 480000 | E35: {=IF($D35="","",$D35*INDEX(Допущения!$C$25:$G$30,MATCH($C35,Допущения!$B$25:$B$30,0),1))} -> 480000 | F35: {=IF($D35="","",$D35*INDEX(Допущения!$C$25:$G$30,MATCH($C35,Допущения!$B$25:$B$30,0),2))} -> 518400 | G35: {=IF($D35="","",$D35*INDEX(Допущения!$C$25:$G$30,MATCH($C35,Допущения!$B$25:$B$30,0),3))} -> 559872 | H35: {=IF($D35="","",$D35*INDEX(Допущения!$C$25:$G$30,MATCH($C35,Допущения!$B$25:$B$30,0),4))} -> 604661.76 | I35: {=IF($D35="","",$D35*INDEX(Допущения!$C$25:$G$30,MATCH($C35,Допущения!$B$25:$B$30,0),5))} -> 653034.7 | J35: =SUM(E35:I35) -> 2815968.5 | L35: Например 6 FTE × $60k. Зависит от арх. варианта!
B36: DevOps / SRE | C36: ФОТ | D36: 120000 | E36: {=IF($D36="","",$D36*INDEX(Допущения!$C$25:$G$30,MATCH($C36,Допущения!$B$25:$B$30,0),1))} -> 120000 | F36: {=IF($D36="","",$D36*INDEX(Допущения!$C$25:$G$30,MATCH($C36,Допущения!$B$25:$B$30,0),2))} -> 129600 | G36: {=IF($D36="","",$D36*INDEX(Допущения!$C$25:$G$30,MATCH($C36,Допущения!$B$25:$B$30,0),3))} -> 139968 | H36: {=IF($D36="","",$D36*INDEX(Допущения!$C$25:$G$30,MATCH($C36,Допущения!$B$25:$B$30,0),4))} -> 151165.44 | I36: {=IF($D36="","",$D36*INDEX(Допущения!$C$25:$G$30,MATCH($C36,Допущения!$B$25:$B$30,0),5))} -> 163258.68 | J36: =SUM(E36:I36) -> 703992.12 | L36: Микросервисы требуют больше SRE, чем монолит
B37: Поддержка и дежурства 24/7 | C37: ФОТ | D37: 210000 | E37: {=IF($D37="","",$D37*INDEX(Допущения!$C$25:$G$30,MATCH($C37,Допущения!$B$25:$B$30,0),1))} -> 210000 | F37: {=IF($D37="","",$D37*INDEX(Допущения!$C$25:$G$30,MATCH($C37,Допущения!$B$25:$B$30,0),2))} -> 226800 | G37: {=IF($D37="","",$D37*INDEX(Допущения!$C$25:$G$30,MATCH($C37,Допущения!$B$25:$B$30,0),3))} -> 244944 | H37: {=IF($D37="","",$D37*INDEX(Допущения!$C$25:$G$30,MATCH($C37,Допущения!$B$25:$B$30,0),4))} -> 264539.52 | I37: {=IF($D37="","",$D37*INDEX(Допущения!$C$25:$G$30,MATCH($C37,Допущения!$B$25:$B$30,0),5))} -> 285702.68 | J37: =SUM(E37:I37) -> 1231986.2 | L37: Требование mission critical: дежурство ночью
B38: Архитектура и менеджмент | C38: ФОТ | D38: 96000 | E38: {=IF($D38="","",$D38*INDEX(Допущения!$C$25:$G$30,MATCH($C38,Допущения!$B$25:$B$30,0),1))} -> 96000 | F38: {=IF($D38="","",$D38*INDEX(Допущения!$C$25:$G$30,MATCH($C38,Допущения!$B$25:$B$30,0),2))} -> 103680 | G38: {=IF($D38="","",$D38*INDEX(Допущения!$C$25:$G$30,MATCH($C38,Допущения!$B$25:$B$30,0),3))} -> 111974.4 | H38: {=IF($D38="","",$D38*INDEX(Допущения!$C$25:$G$30,MATCH($C38,Допущения!$B$25:$B$30,0),4))} -> 120932.35 | I38: {=IF($D38="","",$D38*INDEX(Допущения!$C$25:$G$30,MATCH($C38,Допущения!$B$25:$B$30,0),5))} -> 130606.94 | J38: =SUM(E38:I38) -> 563193.69 | L38: Solution Architect, CTO-функция, PM
B39: Итого по блоку | E39: =SUM(E35:E38) -> 906000 | F39: =SUM(F35:F38) -> 978480 | G39: =SUM(G35:G38) -> 1056758.4 | H39: =SUM(H35:H38) -> 1141299.1 | I39: =SUM(I35:I38) -> 1232603 | J39: =SUM(J35:J38) -> 5315140.5 | K39: =IFERROR(J39/$J$50,0) -> 0.035260659
B41: БЛОК 5. Разовые затраты и комплаенс
B42: Юридический и комплаенс-аудит (NDPR, POPIA, KICA) | C42: фикс | D42: 25000 | E42: {=IF($D42="","",$D42*INDEX(Допущения!$C$25:$G$30,MATCH($C42,Допущения!$B$25:$B$30,0),1))} -> 25000 | F42: {=IF($D42="","",$D42*INDEX(Допущения!$C$25:$G$30,MATCH($C42,Допущения!$B$25:$B$30,0),2))} -> 25000 | G42: {=IF($D42="","",$D42*INDEX(Допущения!$C$25:$G$30,MATCH($C42,Допущения!$B$25:$B$30,0),3))} -> 25000 | H42: {=IF($D42="","",$D42*INDEX(Допущения!$C$25:$G$30,MATCH($C42,Допущения!$B$25:$B$30,0),4))} -> 25000 | I42: {=IF($D42="","",$D42*INDEX(Допущения!$C$25:$G$30,MATCH($C42,Допущения!$B$25:$B$30,0),5))} -> 25000 | J42: =SUM(E42:I42) -> 125000 | L42: Разовая статья — обнули лишние годы вручную
B43: Пентест и аудит безопасности | C43: инфляция | D43: 15000 | E43: {=IF($D43="","",$D43*INDEX(Допущения!$C$25:$G$30,MATCH($C43,Допущения!$B$25:$B$30,0),1))} -> 15000 | F43: {=IF($D43="","",$D43*INDEX(Допущения!$C$25:$G$30,MATCH($C43,Допущения!$B$25:$B$30,0),2))} -> 16800 | G43: {=IF($D43="","",$D43*INDEX(Допущения!$C$25:$G$30,MATCH($C43,Допущения!$B$25:$B$30,0),3))} -> 18816 | H43: {=IF($D43="","",$D43*INDEX(Допущения!$C$25:$G$30,MATCH($C43,Допущения!$B$25:$B$30,0),4))} -> 21073.92 | I43: {=IF($D43="","",$D43*INDEX(Допущения!$C$25:$G$30,MATCH($C43,Допущения!$B$25:$B$30,0),5))} -> 23602.79 | J43: =SUM(E43:I43) -> 95292.71 | L43: Ежегодно, если mission critical
B44: Миграция данных и интеграции при запуске | C44: фикс | D44: 20000 | E44: {=IF($D44="","",$D44*INDEX(Допущения!$C$25:$G$30,MATCH($C44,Допущения!$B$25:$B$30,0),1))} -> 20000 | F44: {=IF($D44="","",$D44*INDEX(Допущения!$C$25:$G$30,MATCH($C44,Допущения!$B$25:$B$30,0),2))} -> 20000 | G44: {=IF($D44="","",$D44*INDEX(Допущения!$C$25:$G$30,MATCH($C44,Допущения!$B$25:$B$30,0),3))} -> 20000 | H44: {=IF($D44="","",$D44*INDEX(Допущения!$C$25:$G$30,MATCH($C44,Допущения!$B$25:$B$30,0),4))} -> 20000 | I44: {=IF($D44="","",$D44*INDEX(Допущения!$C$25:$G$30,MATCH($C44,Допущения!$B$25:$B$30,0),5))} -> 20000 | J44: =SUM(E44:I44) -> 100000 | L44: Разовая статья
B45: Обучение команды и найм | C45: ФОТ | D45: 30000 | E45: {=IF($D45="","",$D45*INDEX(Допущения!$C$25:$G$30,MATCH($C45,Допущения!$B$25:$B$30,0),1))} -> 30000 | F45: {=IF($D45="","",$D45*INDEX(Допущения!$C$25:$G$30,MATCH($C45,Допущения!$B$25:$B$30,0),2))} -> 32400 | G45: {=IF($D45="","",$D45*INDEX(Допущения!$C$25:$G$30,MATCH($C45,Допущения!$B$25:$B$30,0),3))} -> 34992 | H45: {=IF($D45="","",$D45*INDEX(Допущения!$C$25:$G$30,MATCH($C45,Допущения!$B$25:$B$30,0),4))} -> 37791.36 | I45: {=IF($D45="","",$D45*INDEX(Допущения!$C$25:$G$30,MATCH($C45,Допущения!$B$25:$B$30,0),5))} -> 40814.669 | J45: =SUM(E45:I45) -> 175998.03 | L45: Дефицит локальных ИТ-специалистов
B46: Внедрение Kafka — разовые работы | C46: фикс | D46: 5000 | E46: {=IF($D46="","",$D46*INDEX(Допущения!$C$25:$G$30,MATCH($C46,Допущения!$B$25:$B$30,0),1))} -> 5000 | F46: {=IF($D46="","",$D46*INDEX(Допущения!$C$25:$G$30,MATCH($C46,Допущения!$B$25:$B$30,0),2))} -> 5000 | G46: {=IF($D46="","",$D46*INDEX(Допущения!$C$25:$G$30,MATCH($C46,Допущения!$B$25:$B$30,0),3))} -> 5000 | H46: {=IF($D46="","",$D46*INDEX(Допущения!$C$25:$G$30,MATCH($C46,Допущения!$B$25:$B$30,0),4))} -> 5000 | I46: {=IF($D46="","",$D46*INDEX(Допущения!$C$25:$G$30,MATCH($C46,Допущения!$B$25:$B$30,0),5))} -> 5000 | J46: =SUM(E46:I46) -> 25000 | L46: Настройка Kafka-кластера и схем данных. Разовые работы, не входят в регулярную эксплуатацию.
...

Sheet TCO ED
B2: TCO на 5 лет — Africa Delivery
B3: Заполняем колонки «Драйвер роста» и «База, $/год (Год 1)». Годы 1–5 считаются автоматически.
B5: Статья затрат | C5: Драйвер роста | D5: База, $/год (Год 1) | E5: Год 1 | F5: Год 2 | G5: Год 3 | H5: Год 4 | I5: Год 5 | J5: Итого 5 лет | K5: Доля | L5: Комментарий / источник
B6: БЛОК 1. Облачная инфраструктура (OpEx)
B7: Compute: ноды / контейнеры / serverless | C7: пользователи | D7: 42000 | E7: {=IF($D7="","",$D7*INDEX(Допущения!$C$25:$G$30,MATCH($C7,Допущения!$B$25:$B$30,0),1))} -> 42000 | F7: {=IF($D7="","",$D7*INDEX(Допущения!$C$25:$G$30,MATCH($C7,Допущения!$B$25:$B$30,0),2))} -> 252000 | G7: {=IF($D7="","",$D7*INDEX(Допущения!$C$25:$G$30,MATCH($C7,Допущения!$B$25:$B$30,0),3))} -> 840000 | H7: {=IF($D7="","",$D7*INDEX(Допущения!$C$25:$G$30,MATCH($C7,Допущения!$B$25:$B$30,0),4))} -> 2100000 | I7: {=IF($D7="","",$D7*INDEX(Допущения!$C$25:$G$30,MATCH($C7,Допущения!$B$25:$B$30,0),5))} -> 4200000 | J7: =SUM(E7:I7) -> 7434000 | L7: AWS af-south-1, оценка по калькулятору
B8: Управляемые БД (PostgreSQL, реплики) | C8: пользователи | D8: 12000 | E8: {=IF($D8="","",$D8*INDEX(Допущения!$C$25:$G$30,MATCH($C8,Допущения!$B$25:$B$30,0),1))} -> 12000 | F8: {=IF($D8="","",$D8*INDEX(Допущения!$C$25:$G$30,MATCH($C8,Допущения!$B$25:$B$30,0),2))} -> 72000 | G8: {=IF($D8="","",$D8*INDEX(Допущения!$C$25:$G$30,MATCH($C8,Допущения!$B$25:$B$30,0),3))} -> 240000 | H8: {=IF($D8="","",$D8*INDEX(Допущения!$C$25:$G$30,MATCH($C8,Допущения!$B$25:$B$30,0),4))} -> 600000 | I8: {=IF($D8="","",$D8*INDEX(Допущения!$C$25:$G$30,MATCH($C8,Допущения!$B$25:$B$30,0),5))} -> 1200000 | J8: =SUM(E8:I8) -> 2124000 | L8: Managed RDS + read replica
B9: Хранилище объектов и резервные копии | C9: пользователи | D9: 6000 | E9: {=IF($D9="","",$D9*INDEX(Допущения!$C$25:$G$30,MATCH($C9,Допущения!$B$25:$B$30,0),1))} -> 6000 | F9: {=IF($D9="","",$D9*INDEX(Допущения!$C$25:$G$30,MATCH($C9,Допущения!$B$25:$B$30,0),2))} -> 36000 | G9: {=IF($D9="","",$D9*INDEX(Допущения!$C$25:$G$30,MATCH($C9,Допущения!$B$25:$B$30,0),3))} -> 120000 | H9: {=IF($D9="","",$D9*INDEX(Допущения!$C$25:$G$30,MATCH($C9,Допущения!$B$25:$B$30,0),4))} -> 300000 | I9: {=IF($D9="","",$D9*INDEX(Допущения!$C$25:$G$30,MATCH($C9,Допущения!$B$25:$B$30,0),5))} -> 600000 | J9: =SUM(E9:I9) -> 1062000 | L9: Фото товаров, 5000 SKU на старте
B10: CDN и исходящий трафик | C10: пользователи | D10: 12000 | E10: {=IF($D10="","",$D10*INDEX(Допущения!$C$25:$G$30,MATCH($C10,Допущения!$B$25:$B$30,0),1))} -> 12000 | F10: {=IF($D10="","",$D10*INDEX(Допущения!$C$25:$G$30,MATCH($C10,Допущения!$B$25:$B$30,0),2))} -> 72000 | G10: {=IF($D10="","",$D10*INDEX(Допущения!$C$25:$G$30,MATCH($C10,Допущения!$B$25:$B$30,0),3))} -> 240000 | H10: {=IF($D10="","",$D10*INDEX(Допущения!$C$25:$G$30,MATCH($C10,Допущения!$B$25:$B$30,0),4))} -> 600000 | I10: {=IF($D10="","",$D10*INDEX(Допущения!$C$25:$G$30,MATCH($C10,Допущения!$B$25:$B$30,0),5))} -> 1200000 | J10: =SUM(E10:I10) -> 2124000 | L10: 70% трафика — мобильный 3G, картинки WebP
B11: Очереди / стриминг (Kafka, SQS) | C11: пользователи | D11: 12000 | E11: {=IF($D11="","",$D11*INDEX(Допущения!$C$25:$G$30,MATCH($C11,Допущения!$B$25:$B$30,0),1))} -> 12000 | F11: {=IF($D11="","",$D11*INDEX(Допущения!$C$25:$G$30,MATCH($C11,Допущения!$B$25:$B$30,0),2))} -> 72000 | G11: {=IF($D11="","",$D11*INDEX(Допущения!$C$25:$G$30,MATCH($C11,Допущения!$B$25:$B$30,0),3))} -> 240000 | H11: {=IF($D11="","",$D11*INDEX(Допущения!$C$25:$G$30,MATCH($C11,Допущения!$B$25:$B$30,0),4))} -> 600000 | I11: {=IF($D11="","",$D11*INDEX(Допущения!$C$25:$G$30,MATCH($C11,Допущения!$B$25:$B$30,0),5))} -> 1200000 | J11: =SUM(E11:I11) -> 2124000 | L11: Асинхронные заказы и уведомления
B12: Резервный регион / DR | C12: пользователи | D12: 12000 | E12: {=IF($D12="","",$D12*INDEX(Допущения!$C$25:$G$30,MATCH($C12,Допущения!$B$25:$B$30,0),1))} -> 12000 | F12: {=IF($D12="","",$D12*INDEX(Допущения!$C$25:$G$30,MATCH($C12,Допущения!$B$25:$B$30,0),2))} -> 72000 | G12: {=IF($D12="","",$D12*INDEX(Допущения!$C$25:$G$30,MATCH($C12,Допущения!$B$25:$B$30,0),3))} -> 240000 | H12: {=IF($D12="","",$D12*INDEX(Допущения!$C$25:$G$30,MATCH($C12,Допущения!$B$25:$B$30,0),4))} -> 600000 | I12: {=IF($D12="","",$D12*INDEX(Допущения!$C$25:$G$30,MATCH($C12,Допущения!$B$25:$B$30,0),5))} -> 1200000 | J12: =SUM(E12:I12) -> 2124000 | L12: Зависит от выбранной стратегии RTO/RPO
B13: Локальное размещение данных (NDPR, Нигерия) | C13: инфляция | D13: 3000 | E13: {=IF($D13="","",$D13*INDEX(Допущения!$C$25:$G$30,MATCH($C13,Допущения!$B$25:$B$30,0),1))} -> 3000 | F13: {=IF($D13="","",$D13*INDEX(Допущения!$C$25:$G$30,MATCH($C13,Допущения!$B$25:$B$30,0),2))} -> 3360 | G13: {=IF($D13="","",$D13*INDEX(Допущения!$C$25:$G$30,MATCH($C13,Допущения!$B$25:$B$30,0),3))} -> 3763.2 | H13: {=IF($D13="","",$D13*INDEX(Допущения!$C$25:$G$30,MATCH($C13,Допущения!$B$25:$B$30,0),4))} -> 4214.784 | I13: {=IF($D13="","",$D13*INDEX(Допущения!$C$25:$G$30,MATCH($C13,Допущения!$B$25:$B$30,0),5))} -> 4720.5581 | J13: =SUM(E13:I13) -> 19058.542 | L13: Локальный провайдер или партнёр — см. ADR №3
B14: Schema Registry + Kafka Connect | C14: пользователи | D14: 6000 | E14: {=IF($D14="","",$D14*INDEX(Допущения!$C$25:$G$30,MATCH($C14,Допущения!$B$25:$B$30,0),1))} -> 6000 | F14: {=IF($D14="","",$D14*INDEX(Допущения!$C$25:$G$30,MATCH($C14,Допущения!$B$25:$B$30,0),2))} -> 36000 | G14: {=IF($D14="","",$D14*INDEX(Допущения!$C$25:$G$30,MATCH($C14,Допущения!$B$25:$B$30,0),3))} -> 120000 | H14: {=IF($D14="","",$D14*INDEX(Допущения!$C$25:$G$30,MATCH($C14,Допущения!$B$25:$B$30,0),4))} -> 300000 | I14: {=IF($D14="","",$D14*INDEX(Допущения!$C$25:$G$30,MATCH($C14,Допущения!$B$25:$B$30,0),5))} -> 600000 | J14: =SUM(E14:I14) -> 1062000 | L14: Schema Registry (3 узла) + Kafka Connect (2 воркера). Количество событий в Kafka растёт с числом пользователей: каждое действие (просмотр, заказ) — событие. $500/мес на старте. Источник: оценка по GCP/EKS pricing.
B15: Итого по блоку | E15: =SUM(E7:E14) -> 105000 | F15: =SUM(F7:F14) -> 615360 | G15: =SUM(G7:G14) -> 2043763.2 | H15: =SUM(H7:H14) -> 5104214.8 | I15: =SUM(I7:I14) -> 10204721 | J15: =SUM(J7:J14) -> 18073059 | K15: =IFERROR(J15/$J$50,0) -> 0.13070047
B17: БЛОК 2. Лицензии, SaaS и инструменты
B18: Observability (метрики, логи, трейсинг) | C18: пользователи | D18: 7200 | E18: {=IF($D18="","",$D18*INDEX(Допущения!$C$25:$G$30,MATCH($C18,Допущения!$B$25:$B$30,0),1))} -> 7200 | F18: {=IF($D18="","",$D18*INDEX(Допущения!$C$25:$G$30,MATCH($C18,Допущения!$B$25:$B$30,0),2))} -> 43200 | G18: {=IF($D18="","",$D18*INDEX(Допущения!$C$25:$G$30,MATCH($C18,Допущения!$B$25:$B$30,0),3))} -> 144000 | H18: {=IF($D18="","",$D18*INDEX(Допущения!$C$25:$G$30,MATCH($C18,Допущения!$B$25:$B$30,0),4))} -> 360000 | I18: {=IF($D18="","",$D18*INDEX(Допущения!$C$25:$G$30,MATCH($C18,Допущения!$B$25:$B$30,0),5))} -> 720000 | J18: =SUM(E18:I18) -> 1274400 | L18: Объём логов растёт с нагрузкой
B19: CI/CD, репозиторий, артефакты | C19: инфляция | D19: 3600 | E19: {=IF($D19="","",$D19*INDEX(Допущения!$C$25:$G$30,MATCH($C19,Допущения!$B$25:$B$30,0),1))} -> 3600 | F19: {=IF($D19="","",$D19*INDEX(Допущения!$C$25:$G$30,MATCH($C19,Допущения!$B$25:$B$30,0),2))} -> 4032 | G19: {=IF($D19="","",$D19*INDEX(Допущения!$C$25:$G$30,MATCH($C19,Допущения!$B$25:$B$30,0),3))} -> 4515.84 | H19: {=IF($D19="","",$D19*INDEX(Допущения!$C$25:$G$30,MATCH($C19,Допущения!$B$25:$B$30,0),4))} -> 5057.7408 | I19: {=IF($D19="","",$D19*INDEX(Допущения!$C$25:$G$30,MATCH($C19,Допущения!$B$25:$B$30,0),5))} -> 5664.6697 | J19: =SUM(E19:I19) -> 22870.25 | L19: GitHub / GitLab, тарифы на команду
B20: Безопасность: WAF, секреты, антифрод | C20: пользователи | D20: 4800 | E20: {=IF($D20="","",$D20*INDEX(Допущения!$C$25:$G$30,MATCH($C20,Допущения!$B$25:$B$30,0),1))} -> 4800 | F20: {=IF($D20="","",$D20*INDEX(Допущения!$C$25:$G$30,MATCH($C20,Допущения!$B$25:$B$30,0),2))} -> 28800 | G20: {=IF($D20="","",$D20*INDEX(Допущения!$C$25:$G$30,MATCH($C20,Допущения!$B$25:$B$30,0),3))} -> 96000 | H20: {=IF($D20="","",$D20*INDEX(Допущения!$C$25:$G$30,MATCH($C20,Допущения!$B$25:$B$30,0),4))} -> 240000 | I20: {=IF($D20="","",$D20*INDEX(Допущения!$C$25:$G$30,MATCH($C20,Допущения!$B$25:$B$30,0),5))} -> 480000 | J20: =SUM(E20:I20) -> 849600 | L20: Мошенничество на ПВЗ — риск из кейса
B21: WhatsApp Business API (подписка) | C21: инфляция | D21: 2400 | E21: {=IF($D21="","",$D21*INDEX(Допущения!$C$25:$G$30,MATCH($C21,Допущения!$B$25:$B$30,0),1))} -> 2400 | F21: {=IF($D21="","",$D21*INDEX(Допущения!$C$25:$G$30,MATCH($C21,Допущения!$B$25:$B$30,0),2))} -> 2688 | G21: {=IF($D21="","",$D21*INDEX(Допущения!$C$25:$G$30,MATCH($C21,Допущения!$B$25:$B$30,0),3))} -> 3010.56 | H21: {=IF($D21="","",$D21*INDEX(Допущения!$C$25:$G$30,MATCH($C21,Допущения!$B$25:$B$30,0),4))} -> 3371.8272 | I21: {=IF($D21="","",$D21*INDEX(Допущения!$C$25:$G$30,MATCH($C21,Допущения!$B$25:$B$30,0),5))} -> 3776.4465 | J21: =SUM(E21:I21) -> 15246.834 | L21: Канал для продавцов без личного кабинета
B22: Прочее ПО и подписки | C22: инфляция | D22: 2400 | E22: {=IF($D22="","",$D22*INDEX(Допущения!$C$25:$G$30,MATCH($C22,Допущения!$B$25:$B$30,0),1))} -> 2400 | F22: {=IF($D22="","",$D22*INDEX(Допущения!$C$25:$G$30,MATCH($C22,Допущения!$B$25:$B$30,0),2))} -> 2688 | G22: {=IF($D22="","",$D22*INDEX(Допущения!$C$25:$G$30,MATCH($C22,Допущения!$B$25:$B$30,0),3))} -> 3010.56 | H22: {=IF($D22="","",$D22*INDEX(Допущения!$C$25:$G$30,MATCH($C22,Допущения!$B$25:$B$30,0),4))} -> 3371.8272 | I22: {=IF($D22="","",$D22*INDEX(Допущения!$C$25:$G$30,MATCH($C22,Допущения!$B$25:$B$30,0),5))} -> 3776.4465 | J22: =SUM(E22:I22) -> 15246.834 | L22: Таск-трекер, дизайн, аналитика
B23: PactFlow (контрактное тестирование) | C23: пользователи | D23: 3600 | E23: {=IF($D23="","",$D23*INDEX(Допущения!$C$25:$G$30,MATCH($C23,Допущения!$B$25:$B$30,0),1))} -> 3600 | F23: {=IF($D23="","",$D23*INDEX(Допущения!$C$25:$G$30,MATCH($C23,Допущения!$B$25:$B$30,0),2))} -> 21600 | G23: {=IF($D23="","",$D23*INDEX(Допущения!$C$25:$G$30,MATCH($C23,Допущения!$B$25:$B$30,0),3))} -> 72000 | H23: {=IF($D23="","",$D23*INDEX(Допущения!$C$25:$G$30,MATCH($C23,Допущения!$B$25:$B$30,0),4))} -> 180000 | I23: {=IF($D23="","",$D23*INDEX(Допущения!$C$25:$G$30,MATCH($C23,Допущения!$B$25:$B$30,0),5))} -> 360000 | J23: =SUM(E23:I23) -> 637200 | L23: PactFlow Team plan ($300/мес) — контрактное тестирование между сервисами. Число контрактов и частота проверок растут с числом сервисов, которое растёт с числом пользователей. Источник: официальный прайс PactFlow
B24: Итого по блоку | E24: =SUM(E18:E23) -> 24000 | F24: =SUM(F18:F23) -> 103008 | G24: =SUM(G18:G23) -> 322536.96 | H24: =SUM(H18:H23) -> 791801.4 | I24: =SUM(I18:I23) -> 1573217.6 | J24: =SUM(J18:J23) -> 2814563.9 | K24: =IFERROR(J24/$J$50,0) -> 0.02035432
B26: БЛОК 3. Транзакционные расходы (Buy / Partner)
B27: Комиссии платёжных провайдеров | C27: GMV | D27: 375000 | E27: {=IF($D27="","",$D27*INDEX(Допущения!$C$25:$G$30,MATCH($C27,Допущения!$B$25:$B$30,0),1))} -> 375000 | F27: {=IF($D27="","",$D27*INDEX(Допущения!$C$25:$G$30,MATCH($C27,Допущения!$B$25:$B$30,0),2))} -> 2340000 | G27: {=IF($D27="","",$D27*INDEX(Допущения!$C$25:$G$30,MATCH($C27,Допущения!$B$25:$B$30,0),3))} -> 8100000 | H27: {=IF($D27="","",$D27*INDEX(Допущения!$C$25:$G$30,MATCH($C27,Допущения!$B$25:$B$30,0),4))} -> 21000000 | I27: {=IF($D27="","",$D27*INDEX(Допущения!$C$25:$G$30,MATCH($C27,Допущения!$B$25:$B$30,0),5))} -> 43500000 | J27: =SUM(E27:I27) -> 75315000 | L27: ≈3% от GMV: M-Pesa (Кения), Flutterwave / Paystack (Нигерия)
B28: SMS-уведомления | C28: заказы | D28: 24000 | E28: {=IF($D28="","",$D28*INDEX(Допущения!$C$25:$G$30,MATCH($C28,Допущения!$B$25:$B$30,0),1))} -> 24000 | F28: {=IF($D28="","",$D28*INDEX(Допущения!$C$25:$G$30,MATCH($C28,Допущения!$B$25:$B$30,0),2))} -> 144000 | G28: {=IF($D28="","",$D28*INDEX(Допущения!$C$25:$G$30,MATCH($C28,Допущения!$B$25:$B$30,0),3))} -> 480000 | H28: {=IF($D28="","",$D28*INDEX(Допущения!$C$25:$G$30,MATCH($C28,Допущения!$B$25:$B$30,0),4))} -> 1200000 | I28: {=IF($D28="","",$D28*INDEX(Допущения!$C$25:$G$30,MATCH($C28,Допущения!$B$25:$B$30,0),5))} -> 2400000 | J28: =SUM(E28:I28) -> 4248000 | L28: ≈$0,04 за SMS × заказы
