Workbook

Sheet Инструкция
B2: Модель TCO (Total Cost of Ownership) — кейс «Africa Delivery», горизонт 5 лет
B4: Зачем этот файл
B5: Задача | C5: Оценить полную стоимость владения выбранным архитектурным вариантом на 5 лет и использовать цифры как аргумент в ADR №1 («Выбор архитектурного стиля»).
B6: Как использовать | C6: Заполни один и тот же шаблон для каждого рассматриваемого варианта (например: модульный монолит / SOA / микросервисы) — сравнивать нужно итоги, а не ощущения.
B8: Цветовая легенда
B9: Синий текст на жёлтом фоне | C9: Ячейки для заполнения. Только их и редактируем.
B10: Чёрный текст | C10: Формулы. Не трогаем — пересчитаются сами.
B11: Зелёный текст | C11: Ссылка на лист «Допущения».
B13: Порядок работы
B14: Шаг 1 | C14: Лист «Допущения» → блок 1: вбить драйверы бизнеса по годам (активные пользователи, число заказов, средний чек). Из них считается GMV.
B15: Шаг 2 | C15: Лист «Допущения» → блок 2: финансовые допущения (инфляция, рост ФОТ, ставка дисконтирования, резерв, целевой SLO).
B16: Шаг 3 | C16: Лист «TCO» → в колонке «База, $/год (Год 1)» указать затраты первого года по каждой статье. Лишние статьи оставить пустыми, свои — дописать в свободные строки.
B17: Шаг 4 | C17: Лист «TCO» → в колонке «Драйвер роста» выбрать из выпадающего списка, от чего растёт статья: фикс / инфляция / ФОТ / пользователи / заказы / GMV. Годы 2–5 посчитаются сами.
B18: Шаг 5 | C18: Посмотреть блок «Ключевые метрики» внизу листа «TCO»: итог за 5 лет, NPV, стоимость на заказ, проверку бюджета CFO ($9k/мес на облако).
B20: Что важно не забыть в этом кейсе
B21: Бюджет CFO | C21: $9 000/мес на облако на старте. Если Год 1 в блоке «Облачная инфраструктура» не проходит — это архитектурное решение, а не ошибка модели: опиши, что урезаешь.
B22: Цена простоя | C22: Инвестор оценивает минуту простоя в $12 000. Целевой SLO 99,99% = 52,6 мин/год ≈ $631k. Этот риск считается отдельным блоком — сравни его со стоимостью резервирования.
B23: Транзакционные расходы | C23: Комиссии M-Pesa / Flutterwave / Paystack, SMS и WhatsApp растут с GMV и числом заказов и на горизонте 5 лет обычно обгоняют инфраструктуру. Не забудь их — это типичная ошибка.
B24: Сравнение вариантов | C24: Транзакционные расходы (блок 3) почти одинаковы для любой архитектуры — это pass-through от оборота. Варианты архитектуры сравнивай по блокам 1, 2, 4 и 6.
B25: Разовые затраты | C25: Комплаенс-аудит NDPR/POPIA, пентест, миграция — если статья возникает не каждый год, просто перезапиши формулу в нужной ячейке года числом (и покрась в синий).
B26: Люди | C26: ФОТ команды — обычно самая крупная статья TCO. Микросервисы дешевле в масштабировании, но дороже в эксплуатации: это должно быть видно в цифрах, а не только в тексте ADR.
B28: Все числа в файле — примеры для демонстрации формата. Замени их своими оценками и укажи источник в колонке «Комментарий / источник».

Sheet Допущения
B2: Допущения модели TCO — Africa Delivery
B3: Заполняются только ячейки с жёлтой заливкой. Все числа ниже — пример, заменить своими.
B5: 1. Драйверы бизнеса — заполнить
B6: Показатель | C6: Год 1 | D6: Год 2 | E6: Год 3 | F6: Год 4 | G6: Год 5 | H6: Комментарий / источник
B7: Активные пользователи (на конец года) | C7: 50000 | D7: 300000 | E7: 1000000 | F7: 2500000 | G7: 5000000 | H7: Цель кейса: 1М+ пользователей к 12 месяцам, 5 стран
B8: Число заказов в год | C8: 600000 | D8: 3600000 | E8: 12000000 | F8: 30000000 | G8: 60000000 | H8: MVP: 100 продавцов, 5000 SKU. Оценка студента
B9: Средний чек (AOV), $ | C9: 25 | D9: 26 | E9: 27 | F9: 28 | G9: 29 | H9: Оценка студента по рынку (Jumia / Takealot)
B10: GMV, $ в год (расчёт) | C10: =C8*C9 -> 15000000 | D10: =D8*D9 -> 93600000 | E10: =E8*E9 -> 324000000 | F10: =F8*F9 -> 840000000 | G10: =G8*G9 -> 1740000000 | H10: Расчёт: заказы × средний чек
B12: 2. Финансовые допущения — заполнить
B13: Параметр | C13: Значение | H13: Комментарий / источник
B14: Инфляция затрат, % в год | C14: 0.08 | H14: Применяется к статьям с драйвером «инфляция»
B15: Рост ФОТ, % в год | C15: 0.12 | H15: Дефицит ИТ-специалистов на рынке — рост выше инфляции
B16: Ставка дисконтирования, % в год | C16: 0.2 | H16: Для расчёта NPV затрат. Стартап, высокий риск
B17: Резерв на непредвиденное (contingency), % | C17: 0.15 | H17: Надбавка к прямым затратам
B18: Бюджет CFO на облако, $/мес | C18: 5000 | H18: Ограничение из письма CFO
B19: Стоимость минуты простоя, $ | C19: 12000 | H19: Оценка инвестора из условия кейса
B20: Целевой SLO (доступность), % | C20: 0.9999 | H20: Mission critical: 99,99% = 52,6 мин/год
B21: Учитывать стоимость простоя в TCO (1 — да, 0 — нет) | C21: 1 | H21: Переключатель для сценарного анализа
B23: 3. Индексы роста — расчёт, не редактировать
B24: Драйвер | C24: Год 1 | D24: Год 2 | E24: Год 3 | F24: Год 4 | G24: Год 5 | H24: Как считается
B25: фикс | C25: 1 | D25: 1 | E25: 1 | F25: 1 | G25: 1 | H25: Затраты не меняются по годам
B26: инфляция | C26: 1 | D26: =C26*(1+$C$14) -> 1.08 | E26: =D26*(1+$C$14) -> 1.1664 | F26: =E26*(1+$C$14) -> 1.259712 | G26: =F26*(1+$C$14) -> 1.360489 | H26: Год N = Год N-1 × (1 + инфляция)
B27: ФОТ | C27: 1 | D27: =C27*(1+$C$15) -> 1.12 | E27: =D27*(1+$C$15) -> 1.2544 | F27: =E27*(1+$C$15) -> 1.404928 | G27: =F27*(1+$C$15) -> 1.5735194 | H27: Год N = Год N-1 × (1 + рост ФОТ)
B28: пользователи | C28: =C7/$C$7 -> 1 | D28: =D7/$C$7 -> 6 | E28: =E7/$C$7 -> 20 | F28: =F7/$C$7 -> 50 | G28: =G7/$C$7 -> 100 | H28: Пропорционально числу активных пользователей
B29: заказы | C29: =C8/$C$8 -> 1 | D29: =D8/$C$8 -> 6 | E29: =E8/$C$8 -> 20 | F29: =F8/$C$8 -> 50 | G29: =G8/$C$8 -> 100 | H29: Пропорционально числу заказов
B30: GMV | C30: =C10/$C$10 -> 1 | D30: =D10/$C$10 -> 6.24 | E30: =E10/$C$10 -> 21.6 | F30: =F10/$C$10 -> 56 | G30: =G10/$C$10 -> 116 | H30: Пропорционально обороту
B32: Драйвер «пользователи» — упрощение: облачные расходы редко растут строго линейно (есть эффект масштаба и обратный эффект — рост нагрузки на БД). При желании введи свой драйвер отдельной строкой в таблице индексов.

Sheet TCO
B2: TCO на 5 лет — Africa Delivery
B3: Заполняем колонки «Драйвер роста» и «База, $/год (Год 1)». Годы 1–5 считаются автоматически.
B5: Статья затрат | C5: Драйвер роста | D5: База, $/год (Год 1) | E5: Год 1 | F5: Год 2 | G5: Год 3 | H5: Год 4 | I5: Год 5 | J5: Итого 5 лет | K5: Доля | L5: Комментарий / источник
B6: БЛОК 1. Облачная инфраструктура (OpEx)
B7: Compute: ноды / контейнеры / serverless | C7: пользователи | D7: 8400 | E7: {=IF($D7="","",$D7*INDEX(Допущения!$C$25:$G$30,MATCH($C7,Допущения!$B$25:$B$30,0),1))} -> 8400 | F7: {=IF($D7="","",$D7*INDEX(Допущения!$C$25:$G$30,MATCH($C7,Допущения!$B$25:$B$30,0),2))} -> 50400 | G7: {=IF($D7="","",$D7*INDEX(Допущения!$C$25:$G$30,MATCH($C7,Допущения!$B$25:$B$30,0),3))} -> 168000 | H7: {=IF($D7="","",$D7*INDEX(Допущения!$C$25:$G$30,MATCH($C7,Допущения!$B$25:$B$30,0),4))} -> 420000 | I7: {=IF($D7="","",$D7*INDEX(Допущения!$C$25:$G$30,MATCH($C7,Допущения!$B$25:$B$30,0),5))} -> 840000 | J7: =SUM(E7:I7) -> 1486800 | L7: AWS af-south-1, оценка по калькулятору
B8: Управляемые БД (PostgreSQL, реплики) | C8: пользователи | D8: 3600 | E8: =IF($D8="","",$D8*INDEX(Допущения!$C$25:$G$30,MATCH($C8,Допущения!$B$25:$B$30,0),1)) -> 3600 | F8: {=IF($D8="","",$D8*INDEX(Допущения!$C$25:$G$30,MATCH($C8,Допущения!$B$25:$B$30,0),2))} -> 21600 | G8: {=IF($D8="","",$D8*INDEX(Допущения!$C$25:$G$30,MATCH($C8,Допущения!$B$25:$B$30,0),3))} -> 72000 | H8: {=IF($D8="","",$D8*INDEX(Допущения!$C$25:$G$30,MATCH($C8,Допущения!$B$25:$B$30,0),4))} -> 180000 | I8: {=IF($D8="","",$D8*INDEX(Допущения!$C$25:$G$30,MATCH($C8,Допущения!$B$25:$B$30,0),5))} -> 360000 | J8: =SUM(E8:I8) -> 637200 | L8: Managed RDS + read replica
B9: Хранилище объектов и резервные копии | C9: пользователи | D9: 1800 | E9: {=IF($D9="","",$D9*INDEX(Допущения!$C$25:$G$30,MATCH($C9,Допущения!$B$25:$B$30,0),1))} -> 1800 | F9: {=IF($D9="","",$D9*INDEX(Допущения!$C$25:$G$30,MATCH($C9,Допущения!$B$25:$B$30,0),2))} -> 10800 | G9: {=IF($D9="","",$D9*INDEX(Допущения!$C$25:$G$30,MATCH($C9,Допущения!$B$25:$B$30,0),3))} -> 36000 | H9: {=IF($D9="","",$D9*INDEX(Допущения!$C$25:$G$30,MATCH($C9,Допущения!$B$25:$B$30,0),4))} -> 90000 | I9: {=IF($D9="","",$D9*INDEX(Допущения!$C$25:$G$30,MATCH($C9,Допущения!$B$25:$B$30,0),5))} -> 180000 | J9: =SUM(E9:I9) -> 318600 | L9: Фото товаров, 5000 SKU на старте
B10: CDN и исходящий трафик | C10: пользователи | D10: 3600 | E10: {=IF($D10="","",$D10*INDEX(Допущения!$C$25:$G$30,MATCH($C10,Допущения!$B$25:$B$30,0),1))} -> 3600 | F10: {=IF($D10="","",$D10*INDEX(Допущения!$C$25:$G$30,MATCH($C10,Допущения!$B$25:$B$30,0),2))} -> 21600 | G10: {=IF($D10="","",$D10*INDEX(Допущения!$C$25:$G$30,MATCH($C10,Допущения!$B$25:$B$30,0),3))} -> 72000 | H10: {=IF($D10="","",$D10*INDEX(Допущения!$C$25:$G$30,MATCH($C10,Допущения!$B$25:$B$30,0),4))} -> 180000 | I10: {=IF($D10="","",$D10*INDEX(Допущения!$C$25:$G$30,MATCH($C10,Допущения!$B$25:$B$30,0),5))} -> 360000 | J10: =SUM(E10:I10) -> 637200 | L10: 70% трафика — мобильный 3G, картинки WebP
B11: Очереди / стриминг (Kafka, SQS) | C11: пользователи | D11: 1200 | E11: {=IF($D11="","",$D11*INDEX(Допущения!$C$25:$G$30,MATCH($C11,Допущения!$B$25:$B$30,0),1))} -> 1200 | F11: {=IF($D11="","",$D11*INDEX(Допущения!$C$25:$G$30,MATCH($C11,Допущения!$B$25:$B$30,0),2))} -> 7200 | G11: {=IF($D11="","",$D11*INDEX(Допущения!$C$25:$G$30,MATCH($C11,Допущения!$B$25:$B$30,0),3))} -> 24000 | H11: {=IF($D11="","",$D11*INDEX(Допущения!$C$25:$G$30,MATCH($C11,Допущения!$B$25:$B$30,0),4))} -> 60000 | I11: {=IF($D11="","",$D11*INDEX(Допущения!$C$25:$G$30,MATCH($C11,Допущения!$B$25:$B$30,0),5))} -> 120000 | J11: =SUM(E11:I11) -> 212400 | L11: Асинхронные заказы и уведомления
B12: Резервный регион / DR | C12: пользователи | D12: 2400 | E12: {=IF($D12="","",$D12*INDEX(Допущения!$C$25:$G$30,MATCH($C12,Допущения!$B$25:$B$30,0),1))} -> 2400 | F12: {=IF($D12="","",$D12*INDEX(Допущения!$C$25:$G$30,MATCH($C12,Допущения!$B$25:$B$30,0),2))} -> 14400 | G12: {=IF($D12="","",$D12*INDEX(Допущения!$C$25:$G$30,MATCH($C12,Допущения!$B$25:$B$30,0),3))} -> 48000 | H12: {=IF($D12="","",$D12*INDEX(Допущения!$C$25:$G$30,MATCH($C12,Допущения!$B$25:$B$30,0),4))} -> 120000 | I12: {=IF($D12="","",$D12*INDEX(Допущения!$C$25:$G$30,MATCH($C12,Допущения!$B$25:$B$30,0),5))} -> 240000 | J12: =SUM(E12:I12) -> 424800 | L12: Зависит от выбранной стратегии RTO/RPO
B13: Локальное размещение данных (NDPR, Нигерия) | C13: инфляция | D13: 4000 | E13: {=IF($D13="","",$D13*INDEX(Допущения!$C$25:$G$30,MATCH($C13,Допущения!$B$25:$B$30,0),1))} -> 4000 | F13: {=IF($D13="","",$D13*INDEX(Допущения!$C$25:$G$30,MATCH($C13,Допущения!$B$25:$B$30,0),2))} -> 4320 | G13: {=IF($D13="","",$D13*INDEX(Допущения!$C$25:$G$30,MATCH($C13,Допущения!$B$25:$B$30,0),3))} -> 4665.6 | H13: {=IF($D13="","",$D13*INDEX(Допущения!$C$25:$G$30,MATCH($C13,Допущения!$B$25:$B$30,0),4))} -> 5038.848 | I13: {=IF($D13="","",$D13*INDEX(Допущения!$C$25:$G$30,MATCH($C13,Допущения!$B$25:$B$30,0),5))} -> 5441.9558 | J13: =SUM(E13:I13) -> 23466.404 | L13: Локальный провайдер или партнёр — см. ADR №3
C14: фикс | E14: {=IF($D14="","",$D14*INDEX(Допущения!$C$25:$G$30,MATCH($C14,Допущения!$B$25:$B$30,0),1))} | F14: {=IF($D14="","",$D14*INDEX(Допущения!$C$25:$G$30,MATCH($C14,Допущения!$B$25:$B$30,0),2))} | G14: {=IF($D14="","",$D14*INDEX(Допущения!$C$25:$G$30,MATCH($C14,Допущения!$B$25:$B$30,0),3))} | H14: {=IF($D14="","",$D14*INDEX(Допущения!$C$25:$G$30,MATCH($C14,Допущения!$B$25:$B$30,0),4))} | I14: {=IF($D14="","",$D14*INDEX(Допущения!$C$25:$G$30,MATCH($C14,Допущения!$B$25:$B$30,0),5))} | J14: =SUM(E14:I14) -> 0 | L14: Своя статья
B15: Итого по блоку | E15: =SUM(E7:E14) -> 25000 | F15: =SUM(F7:F14) -> 130320 | G15: =SUM(G7:G14) -> 424665.6 | H15: =SUM(H7:H14) -> 1055038.8 | I15: =SUM(I7:I14) -> 2105442 | J15: =SUM(J7:J14) -> 3740466.4 | K15: =IFERROR(J15/$J$51,0) -> 0.03064115
B17: БЛОК 2. Лицензии, SaaS и инструменты
B18: Observability (метрики, логи, трейсинг) | C18: пользователи | D18: 1200 | E18: {=IF($D18="","",$D18*INDEX(Допущения!$C$25:$G$30,MATCH($C18,Допущения!$B$25:$B$30,0),1))} -> 1200 | F18: {=IF($D18="","",$D18*INDEX(Допущения!$C$25:$G$30,MATCH($C18,Допущения!$B$25:$B$30,0),2))} -> 7200 | G18: {=IF($D18="","",$D18*INDEX(Допущения!$C$25:$G$30,MATCH($C18,Допущения!$B$25:$B$30,0),3))} -> 24000 | H18: {=IF($D18="","",$D18*INDEX(Допущения!$C$25:$G$30,MATCH($C18,Допущения!$B$25:$B$30,0),4))} -> 60000 | I18: {=IF($D18="","",$D18*INDEX(Допущения!$C$25:$G$30,MATCH($C18,Допущения!$B$25:$B$30,0),5))} -> 120000 | J18: =SUM(E18:I18) -> 212400 | L18: Объём логов растёт с нагрузкой
B19: CI/CD, репозиторий, артефакты | C19: инфляция | D19: 1200 | E19: {=IF($D19="","",$D19*INDEX(Допущения!$C$25:$G$30,MATCH($C19,Допущения!$B$25:$B$30,0),1))} -> 1200 | F19: {=IF($D19="","",$D19*INDEX(Допущения!$C$25:$G$30,MATCH($C19,Допущения!$B$25:$B$30,0),2))} -> 1296 | G19: {=IF($D19="","",$D19*INDEX(Допущения!$C$25:$G$30,MATCH($C19,Допущения!$B$25:$B$30,0),3))} -> 1399.68 | H19: {=IF($D19="","",$D19*INDEX(Допущения!$C$25:$G$30,MATCH($C19,Допущения!$B$25:$B$30,0),4))} -> 1511.6544 | I19: {=IF($D19="","",$D19*INDEX(Допущения!$C$25:$G$30,MATCH($C19,Допущения!$B$25:$B$30,0),5))} -> 1632.5868 | J19: =SUM(E19:I19) -> 7039.9212 | L19: GitHub / GitLab, тарифы на команду
B20: Безопасность: WAF, секреты, антифрод | C20: пользователи | D20: 1800 | E20: {=IF($D20="","",$D20*INDEX(Допущения!$C$25:$G$30,MATCH($C20,Допущения!$B$25:$B$30,0),1))} -> 1800 | F20: {=IF($D20="","",$D20*INDEX(Допущения!$C$25:$G$30,MATCH($C20,Допущения!$B$25:$B$30,0),2))} -> 10800 | G20: {=IF($D20="","",$D20*INDEX(Допущения!$C$25:$G$30,MATCH($C20,Допущения!$B$25:$B$30,0),3))} -> 36000 | H20: {=IF($D20="","",$D20*INDEX(Допущения!$C$25:$G$30,MATCH($C20,Допущения!$B$25:$B$30,0),4))} -> 90000 | I20: {=IF($D20="","",$D20*INDEX(Допущения!$C$25:$G$30,MATCH($C20,Допущения!$B$25:$B$30,0),5))} -> 180000 | J20: =SUM(E20:I20) -> 318600 | L20: Мошенничество на ПВЗ — риск из кейса
B21: WhatsApp Business API (подписка) | C21: инфляция | D21: 2400 | E21: {=IF($D21="","",$D21*INDEX(Допущения!$C$25:$G$30,MATCH($C21,Допущения!$B$25:$B$30,0),1))} -> 2400 | F21: {=IF($D21="","",$D21*INDEX(Допущения!$C$25:$G$30,MATCH($C21,Допущения!$B$25:$B$30,0),2))} -> 2592 | G21: {=IF($D21="","",$D21*INDEX(Допущения!$C$25:$G$30,MATCH($C21,Допущения!$B$25:$B$30,0),3))} -> 2799.36 | H21: {=IF($D21="","",$D21*INDEX(Допущения!$C$25:$G$30,MATCH($C21,Допущения!$B$25:$B$30,0),4))} -> 3023.3088 | I21: {=IF($D21="","",$D21*INDEX(Допущения!$C$25:$G$30,MATCH($C21,Допущения!$B$25:$B$30,0),5))} -> 3265.1735 | J21: =SUM(E21:I21) -> 14079.842 | L21: Канал для продавцов без личного кабинета
B22: Прочее ПО и подписки | C22: инфляция | D22: 1200 | E22: {=IF($D22="","",$D22*INDEX(Допущения!$C$25:$G$30,MATCH($C22,Допущения!$B$25:$B$30,0),1))} -> 1200 | F22: {=IF($D22="","",$D22*INDEX(Допущения!$C$25:$G$30,MATCH($C22,Допущения!$B$25:$B$30,0),2))} -> 1296 | G22: {=IF($D22="","",$D22*INDEX(Допущения!$C$25:$G$30,MATCH($C22,Допущения!$B$25:$B$30,0),3))} -> 1399.68 | H22: {=IF($D22="","",$D22*INDEX(Допущения!$C$25:$G$30,MATCH($C22,Допущения!$B$25:$B$30,0),4))} -> 1511.6544 | I22: {=IF($D22="","",$D22*INDEX(Допущения!$C$25:$G$30,MATCH($C22,Допущения!$B$25:$B$30,0),5))} -> 1632.5868 | J22: =SUM(E22:I22) -> 7039.9212 | L22: Таск-трекер, дизайн, аналитика
C23: фикс | E23: {=IF($D23="","",$D23*INDEX(Допущения!$C$25:$G$30,MATCH($C23,Допущения!$B$25:$B$30,0),1))} | F23: {=IF($D23="","",$D23*INDEX(Допущения!$C$25:$G$30,MATCH($C23,Допущения!$B$25:$B$30,0),2))} | G23: {=IF($D23="","",$D23*INDEX(Допущения!$C$25:$G$30,MATCH($C23,Допущения!$B$25:$B$30,0),3))} | H23: {=IF($D23="","",$D23*INDEX(Допущения!$C$25:$G$30,MATCH($C23,Допущения!$B$25:$B$30,0),4))} | I23: {=IF($D23="","",$D23*INDEX(Допущения!$C$25:$G$30,MATCH($C23,Допущения!$B$25:$B$30,0),5))} | J23: =SUM(E23:I23) -> 0 | L23: Своя статья
B24: Итого по блоку | E24: =SUM(E18:E23) -> 7800 | F24: =SUM(F18:F23) -> 23184 | G24: =SUM(G18:G23) -> 65598.72 | H24: =SUM(H18:H23) -> 156046.62 | I24: =SUM(I18:I23) -> 306530.35 | J24: =SUM(J18:J23) -> 559159.68 | K24: =IFERROR(J24/$J$51,0) -> 0.0045805239
B26: БЛОК 3. Транзакционные расходы (Buy / Partner)
B27: Комиссии платёжных провайдеров | C27: GMV | D27: 375000 | E27: {=IF($D27="","",$D27*INDEX(Допущения!$C$25:$G$30,MATCH($C27,Допущения!$B$25:$B$30,0),1))} -> 375000 | F27: {=IF($D27="","",$D27*INDEX(Допущения!$C$25:$G$30,MATCH($C27,Допущения!$B$25:$B$30,0),2))} -> 2340000 | G27: {=IF($D27="","",$D27*INDEX(Допущения!$C$25:$G$30,MATCH($C27,Допущения!$B$25:$B$30,0),3))} -> 8100000 | H27: {=IF($D27="","",$D27*INDEX(Допущения!$C$25:$G$30,MATCH($C27,Допущения!$B$25:$B$30,0),4))} -> 21000000 | I27: {=IF($D27="","",$D27*INDEX(Допущения!$C$25:$G$30,MATCH($C27,Допущения!$B$25:$B$30,0),5))} -> 43500000 | J27: =SUM(E27:I27) -> 75315000 | L27: ≈3% от GMV: M-Pesa (Кения), Flutterwave / Paystack (Нигерия)
B28: SMS-уведомления | C28: заказы | D28: 24000 | E28: {=IF($D28="","",$D28*INDEX(Допущения!$C$25:$G$30,MATCH($C28,Допущения!$B$25:$B$30,0),1))} -> 24000 | F28: {=IF($D28="","",$D28*INDEX(Допущения!$C$25:$G$30,MATCH($C28,Допущения!$B$25:$B$30,0),2))} -> 144000 | G28: {=IF($D28="","",$D28*INDEX(Допущения!$C$25:$G$30,MATCH($C28,Допущения!$B$25:$B$30,0),3))} -> 480000 | H28: {=IF($D28="","",$D28*INDEX(Допущения!$C$25:$G$30,MATCH($C28,Допущения!$B$25:$B$30,0),4))} -> 1200000 | I28: {=IF($D28="","",$D28*INDEX(Допущения!$C$25:$G$30,MATCH($C28,Допущения!$B$25:$B$30,0),5))} -> 2400000 | J28: =SUM(E28:I28) -> 4248000 | L28: ≈$0,04 за SMS × заказы
B29: WhatsApp-сообщения (за диалог) | C29: заказы | D29: 18000 | E29: {=IF($D29="","",$D29*INDEX(Допущения!$C$25:$G$30,MATCH($C29,Допущения!$B$25:$B$30,0),1))} -> 18000 | F29: {=IF($D29="","",$D29*INDEX(Допущения!$C$25:$G$30,MATCH($C29,Допущения!$B$25:$B$30,0),2))} -> 108000 | G29: {=IF($D29="","",$D29*INDEX(Допущения!$C$25:$G$30,MATCH($C29,Допущения!$B$25:$B$30,0),3))} -> 360000 | H29: {=IF($D29="","",$D29*INDEX(Допущения!$C$25:$G$30,MATCH($C29,Допущения!$B$25:$B$30,0),4))} -> 900000 | I29: {=IF($D29="","",$D29*INDEX(Допущения!$C$25:$G$30,MATCH($C29,Допущения!$B$25:$B$30,0),5))} -> 1800000 | J29: =SUM(E29:I29) -> 3186000 | L29: Тариф Meta за conversation
B30: Логистика: интеграции и комиссии партнёров | C30: заказы | D30: 90000 | E30: {=IF($D30="","",$D30*INDEX(Допущения!$C$25:$G$30,MATCH($C30,Допущения!$B$25:$B$30,0),1))} -> 90000 | F30: {=IF($D30="","",$D30*INDEX(Допущения!$C$25:$G$30,MATCH($C30,Допущения!$B$25:$B$30,0),2))} -> 540000 | G30: {=IF($D30="","",$D30*INDEX(Допущения!$C$25:$G$30,MATCH($C30,Допущения!$B$25:$B$30,0),3))} -> 1800000 | H30: {=IF($D30="","",$D30*INDEX(Допущения!$C$25:$G$30,MATCH($C30,Допущения!$B$25:$B$30,0),4))} -> 4500000 | I30: {=IF($D30="","",$D30*INDEX(Допущения!$C$25:$G$30,MATCH($C30,Допущения!$B$25:$B$30,0),5))} -> 9000000 | J30: =SUM(E30:I30) -> 15930000 | L30: Sendbox (Нигерия), Sendy (Кения)
C31: фикс | E31: {=IF($D31="","",$D31*INDEX(Допущения!$C$25:$G$30,MATCH($C31,Допущения!$B$25:$B$30,0),1))} | F31: {=IF($D31="","",$D31*INDEX(Допущения!$C$25:$G$30,MATCH($C31,Допущения!$B$25:$B$30,0),2))} | G31: {=IF($D31="","",$D31*INDEX(Допущения!$C$25:$G$30,MATCH($C31,Допущения!$B$25:$B$30,0),3))} | H31: {=IF($D31="","",$D31*INDEX(Допущения!$C$25:$G$30,MATCH($C31,Допущения!$B$25:$B$30,0),4))} | I31: {=IF($D31="","",$D31*INDEX(Допущения!$C$25:$G$30,MATCH($C31,Допущения!$B$25:$B$30,0),5))} | J31: =SUM(E31:I31) -> 0 | L31: Своя статья
B32: Итого по блоку | E32: =SUM(E27:E31) -> 507000 | F32: =SUM(F27:F31) -> 3132000 | G32: =SUM(G27:G31) -> 10740000 | H32: =SUM(H27:H31) -> 27600000 | I32: =SUM(I27:I31) -> 56700000 | J32: =SUM(J27:J31) -> 98679000 | K32: =IFERROR(J32/$J$51,0) -> 0.80835856
B34: БЛОК 4. Команда (ФОТ)
B35: Разработка (FTE × годовая ставка) | C35: ФОТ | D35: 180000 | E35: {=IF($D35="","",$D35*INDEX(Допущения!$C$25:$G$30,MATCH($C35,Допущения!$B$25:$B$30,0),1))} -> 180000 | F35: {=IF($D35="","",$D35*INDEX(Допущения!$C$25:$G$30,MATCH($C35,Допущения!$B$25:$B$30,0),2))} -> 201600 | G35: {=IF($D35="","",$D35*INDEX(Допущения!$C$25:$G$30,MATCH($C35,Допущения!$B$25:$B$30,0),3))} -> 225792 | H35: {=IF($D35="","",$D35*INDEX(Допущения!$C$25:$G$30,MATCH($C35,Допущения!$B$25:$B$30,0),4))} -> 252887.04 | I35: {=IF($D35="","",$D35*INDEX(Допущения!$C$25:$G$30,MATCH($C35,Допущения!$B$25:$B$30,0),5))} -> 283233.48 | J35: =SUM(E35:I35) -> 1143512.5 | L35: Например 6 FTE × $60k. Зависит от арх. варианта!
B36: DevOps / SRE | C36: ФОТ | D36: 60000 | E36: {=IF($D36="","",$D36*INDEX(Допущения!$C$25:$G$30,MATCH($C36,Допущения!$B$25:$B$30,0),1))} -> 60000 | F36: {=IF($D36="","",$D36*INDEX(Допущения!$C$25:$G$30,MATCH($C36,Допущения!$B$25:$B$30,0),2))} -> 67200 | G36: {=IF($D36="","",$D36*INDEX(Допущения!$C$25:$G$30,MATCH($C36,Допущения!$B$25:$B$30,0),3))} -> 75264 | H36: {=IF($D36="","",$D36*INDEX(Допущения!$C$25:$G$30,MATCH($C36,Допущения!$B$25:$B$30,0),4))} -> 84295.68 | I36: {=IF($D36="","",$D36*INDEX(Допущения!$C$25:$G$30,MATCH($C36,Допущения!$B$25:$B$30,0),5))} -> 94411.162 | J36: =SUM(E36:I36) -> 381170.84 | L36: Микросервисы требуют больше SRE, чем монолит
B37: Поддержка и дежурства 24/7 | C37: ФОТ | D37: 70000 | E37: {=IF($D37="","",$D37*INDEX(Допущения!$C$25:$G$30,MATCH($C37,Допущения!$B$25:$B$30,0),1))} -> 70000 | F37: {=IF($D37="","",$D37*INDEX(Допущения!$C$25:$G$30,MATCH($C37,Допущения!$B$25:$B$30,0),2))} -> 78400 | G37: {=IF($D37="","",$D37*INDEX(Допущения!$C$25:$G$30,MATCH($C37,Допущения!$B$25:$B$30,0),3))} -> 87808 | H37: {=IF($D37="","",$D37*INDEX(Допущения!$C$25:$G$30,MATCH($C37,Допущения!$B$25:$B$30,0),4))} -> 98344.96 | I37: {=IF($D37="","",$D37*INDEX(Допущения!$C$25:$G$30,MATCH($C37,Допущения!$B$25:$B$30,0),5))} -> 110146.36 | J37: =SUM(E37:I37) -> 444699.32 | L37: Требование mission critical: дежурство ночью
B38: Архитектура и менеджмент | C38: ФОТ | D38: 150000 | E38: {=IF($D38="","",$D38*INDEX(Допущения!$C$25:$G$30,MATCH($C38,Допущения!$B$25:$B$30,0),1))} -> 150000 | F38: {=IF($D38="","",$D38*INDEX(Допущения!$C$25:$G$30,MATCH($C38,Допущения!$B$25:$B$30,0),2))} -> 168000 | G38: {=IF($D38="","",$D38*INDEX(Допущения!$C$25:$G$30,MATCH($C38,Допущения!$B$25:$B$30,0),3))} -> 188160 | H38: {=IF($D38="","",$D38*INDEX(Допущения!$C$25:$G$30,MATCH($C38,Допущения!$B$25:$B$30,0),4))} -> 210739.2 | I38: {=IF($D38="","",$D38*INDEX(Допущения!$C$25:$G$30,MATCH($C38,Допущения!$B$25:$B$30,0),5))} -> 236027.9 | J38: =SUM(E38:I38) -> 952927.1 | L38: Solution Architect, CTO-функция, PM
C39: фикс | E39: {=IF($D39="","",$D39*INDEX(Допущения!$C$25:$G$30,MATCH($C39,Допущения!$B$25:$B$30,0),1))} | F39: {=IF($D39="","",$D39*INDEX(Допущения!$C$25:$G$30,MATCH($C39,Допущения!$B$25:$B$30,0),2))} | G39: {=IF($D39="","",$D39*INDEX(Допущения!$C$25:$G$30,MATCH($C39,Допущения!$B$25:$B$30,0),3))} | H39: {=IF($D39="","",$D39*INDEX(Допущения!$C$25:$G$30,MATCH($C39,Допущения!$B$25:$B$30,0),4))} | I39: {=IF($D39="","",$D39*INDEX(Допущения!$C$25:$G$30,MATCH($C39,Допущения!$B$25:$B$30,0),5))} | J39: =SUM(E39:I39) -> 0 | L39: Своя статья
B40: Итого по блоку | E40: =SUM(E35:E39) -> 460000 | F40: =SUM(F35:F39) -> 515200 | G40: =SUM(G35:G39) -> 577024 | H40: =SUM(H35:H39) -> 646266.88 | I40: =SUM(I35:I39) -> 723818.91 | J40: =SUM(J35:J39) -> 2922309.8 | K40: =IFERROR(J40/$J$51,0) -> 0.023938975
B42: БЛОК 5. Разовые затраты и комплаенс
B43: Юридический и комплаенс-аудит (NDPR, POPIA, KICA) | C43: фикс | D43: 25000 | E43: {=IF($D43="","",$D43*INDEX(Допущения!$C$25:$G$30,MATCH($C43,Допущения!$B$25:$B$30,0),1))} -> 25000 | F43: {=IF($D43="","",$D43*INDEX(Допущения!$C$25:$G$30,MATCH($C43,Допущения!$B$25:$B$30,0),2))} -> 25000 | G43: {=IF($D43="","",$D43*INDEX(Допущения!$C$25:$G$30,MATCH($C43,Допущения!$B$25:$B$30,0),3))} -> 25000 | H43: {=IF($D43="","",$D43*INDEX(Допущения!$C$25:$G$30,MATCH($C43,Допущения!$B$25:$B$30,0),4))} -> 25000 | I43: {=IF($D43="","",$D43*INDEX(Допущения!$C$25:$G$30,MATCH($C43,Допущения!$B$25:$B$30,0),5))} -> 25000 | J43: =SUM(E43:I43) -> 125000 | L43: Разовая статья — обнули лишние годы вручную
B44: Пентест и аудит безопасности | C44: инфляция | D44: 15000 | E44: {=IF($D44="","",$D44*INDEX(Допущения!$C$25:$G$30,MATCH($C44,Допущения!$B$25:$B$30,0),1))} -> 15000 | F44: {=IF($D44="","",$D44*INDEX(Допущения!$C$25:$G$30,MATCH($C44,Допущения!$B$25:$B$30,0),2))} -> 16200 | G44: {=IF($D44="","",$D44*INDEX(Допущения!$C$25:$G$30,MATCH($C44,Допущения!$B$25:$B$30,0),3))} -> 17496 | H44: {=IF($D44="","",$D44*INDEX(Допущения!$C$25:$G$30,MATCH($C44,Допущения!$B$25:$B$30,0),4))} -> 18895.68 | I44: {=IF($D44="","",$D44*INDEX(Допущения!$C$25:$G$30,MATCH($C44,Допущения!$B$25:$B$30,0),5))} -> 20407.334 | J44: =SUM(E44:I44) -> 87999.014 | L44: Ежегодно, если mission critical
B45: Миграция данных и интеграции при запуске | C45: фикс | D45: 1000 | E45: {=IF($D45="","",$D45*INDEX(Допущения!$C$25:$G$30,MATCH($C45,Допущения!$B$25:$B$30,0),1))} -> 1000 | F45: {=IF($D45="","",$D45*INDEX(Допущения!$C$25:$G$30,MATCH($C45,Допущения!$B$25:$B$30,0),2))} -> 1000 | G45: {=IF($D45="","",$D45*INDEX(Допущения!$C$25:$G$30,MATCH($C45,Допущения!$B$25:$B$30,0),3))} -> 1000 | H45: {=IF($D45="","",$D45*INDEX(Допущения!$C$25:$G$30,MATCH($C45,Допущения!$B$25:$B$30,0),4))} -> 1000 | I45: {=IF($D45="","",$D45*INDEX(Допущения!$C$25:$G$30,MATCH($C45,Допущения!$B$25:$B$30,0),5))} -> 1000 | J45: =SUM(E45:I45) -> 5000 | L45: Разовая статья
B46: Обучение команды и найм | C46: ФОТ | D46: 5000 | E46: {=IF($D46="","",$D46*INDEX(Допущения!$C$25:$G$30,MATCH($C46,Допущения!$B$25:$B$30,0),1))} -> 5000 | F46: {=IF($D46="","",$D46*INDEX(Допущения!$C$25:$G$30,MATCH($C46,Допущения!$B$25:$B$30,0),2))} -> 5600 | G46: {=IF($D46="","",$D46*INDEX(Допущения!$C$25:$G$30,MATCH($C46,Допущения!$B$25:$B$30,0),3))} -> 6272 | H46: {=IF($D46="","",$D46*INDEX(Допущения!$C$25:$G$30,MATCH($C46,Допущения!$B$25:$B$30,0),4))} -> 7024.64 | I46: {=IF($D46="","",$D46*INDEX(Допущения!$C$25:$G$30,MATCH($C46,Допущения!$B$25:$B$30,0),5))} -> 7867.5968 | J46: =SUM(E46:I46) -> 31764.237 | L46: Дефицит локальных ИТ-специалистов
...
